Workbook

Sheet LISTADO
Q1: =SUM(Q3:Q513)
B2: ÍTEM | C2: PROYECTO | D2: ID LOTE | E2: ETAPA | F2: # LOTES | G2: MANZANA | H2: LOTE | I2: AREA (M2) | J2: PRECIO M2 | K2: PRECIO DE LOTE | L2: ESTADO | M2: CONTRATO | N2: PRECIO DE VENTA | O2: ESCRITURA | P2: FECHA DE ESCRITURA | Q2: % ESCRITURADO | R2: A NOMBRE DE : | S2: OBSERVACIÓN | U2: LOTES RELACIONADOS | V2: ALERTA
B3: 1 | C3: LA CEIBA | D3: ="LC" & E3 & " - " & G3 & " - " & H3 | E3: 1 | F3: 1 | G3: 1 | H3: 1 | I3: 1363.4231 | K3: 0 | L3: NO APTO PARA VENTA | N3: =I3*J3 | U3: =IF($D3="","",IF(OR($F3>1,ISNUMBER(SEARCH(" Y ",$D3)),(LEN($D3)-LEN(SUBSTITUTE(UPPER($D3),"LC","")))/2>1),"MÚLTIPLE","INDIVIDUAL")) | V3: =IF($D3="","",IF(AND(ISNUMBER(SEARCH(" Y ",$D3)),$F3<2),"REVISAR # LOTES",""))
B4: 2 | C4: LA CEIBA | D4: LC1 - 2 Y 3 | E4: 1 | F4: 2 | G4: 1 | H4: 2 - 3 | I4: 196 | K4: 55000000 | L4: VENDIDO | M4: SI | N4: =K4 | U4: =IF($D4="","",IF(OR($F4>1,ISNUMBER(SEARCH(" Y ",$D4)),(LEN($D4)-LEN(SUBSTITUTE(UPPER($D4),"LC","")))/2>1),"MÚLTIPLE","INDIVIDUAL")) | V4: =IF($D4="","",IF(AND(ISNUMBER(SEARCH(" Y ",$D4)),$F4<2),"REVISAR # LOTES",""))
B5: 3 | C5: LA CEIBA | D5: LC1 - 1 - 4 | E5: 1 | F5: 1 | G5: 1 | H5: 4 | I5: 98 | K5: 25000000 | L5: VENDIDO | M5: SI | N5: =K5 | O5: OK | Q5: 9.8e-05 | R5: RUBEN FABIAN BUSTOS | U5: =IF($D5="","",IF(OR($F5>1,ISNUMBER(SEARCH(" Y ",$D5)),(LEN($D5)-LEN(SUBSTITUTE(UPPER($D5),"LC","")))/2>1),"MÚLTIPLE","INDIVIDUAL")) | V5: =IF($D5="","",IF(AND(ISNUMBER(SEARCH(" Y ",$D5)),$F5<2),"REVISAR # LOTES",""))
B6: 4 | C6: LA CEIBA | D6: LC1 - 1 - 5 | E6: 1 | F6: 1 | G6: 1 | H6: 5 | I6: 115.643 | K6: 29500000 | L6: VENDIDO | M6: NO | N6: =K6 | U6: =IF($D6="","",IF(OR($F6>1,ISNUMBER(SEARCH(" Y ",$D6)),(LEN($D6)-LEN(SUBSTITUTE(UPPER($D6),"LC","")))/2>1),"MÚLTIPLE","INDIVIDUAL")) | V6: =IF($D6="","",IF(AND(ISNUMBER(SEARCH(" Y ",$D6)),$F6<2),"REVISAR # LOTES",""))
B7: 5 | C7: LA CEIBA | D7: LC1 - 2 - 1 | E7: 1 | F7: 1 | G7: 2 | H7: 1 | I7: 98 | K7: 30000000 | L7: VENDIDO | M7: SI | N7: =K7 | U7: =IF($D7="","",IF(OR($F7>1,ISNUMBER(SEARCH(" Y ",$D7)),(LEN($D7)-LEN(SUBSTITUTE(UPPER($D7),"LC","")))/2>1),"MÚLTIPLE","INDIVIDUAL")) | V7: =IF($D7="","",IF(AND(ISNUMBER(SEARCH(" Y ",$D7)),$F7<2),"REVISAR # LOTES",""))
B8: 6 | C8: LA CEIBA | D8: LC1 - 2 - 2 | E8: 1 | F8: 1 | G8: 2 | H8: 2 | I8: 98 | K8: 25000000 | L8: VENDIDO | M8: SI | N8: =K8 | U8: =IF($D8="","",IF(OR($F8>1,ISNUMBER(SEARCH(" Y ",$D8)),(LEN($D8)-LEN(SUBSTITUTE(UPPER($D8),"LC","")))/2>1),"MÚLTIPLE","INDIVIDUAL")) | V8: =IF($D8="","",IF(AND(ISNUMBER(SEARCH(" Y ",$D8)),$F8<2),"REVISAR # LOTES",""))
B9: 7 | C9: LA CEIBA | D9: LC1 - 2 - 3 | E9: 1 | F9: 1 | G9: 2 | H9: 3 | I9: 98 | K9: 25000000 | L9: CEDIDO EN FORMA DE PAGO | N9: =K9 | U9: =IF($D9="","",IF(OR($F9>1,ISNUMBER(SEARCH(" Y ",$D9)),(LEN($D9)-LEN(SUBSTITUTE(UPPER($D9),"LC","")))/2>1),"MÚLTIPLE","INDIVIDUAL")) | V9: =IF($D9="","",IF(AND(ISNUMBER(SEARCH(" Y ",$D9)),$F9<2),"REVISAR # LOTES",""))
B10: 8 | C10: LA CEIBA | D10: LC1 - 2 - 4 | E10: 1 | F10: 1 | G10: 2 | H10: 4 | I10: 98 | K10: 25000000 | L10: CEDIDO EN FORMA DE PAGO | N10: =K10 | U10: =IF($D10="","",IF(OR($F10>1,ISNUMBER(SEARCH(" Y ",$D10)),(LEN($D10)-LEN(SUBSTITUTE(UPPER($D10),"LC","")))/2>1),"MÚLTIPLE","INDIVIDUAL")) | V10: =IF($D10="","",IF(AND(ISNUMBER(SEARCH(" Y ",$D10)),$F10<2),"REVISAR # LOTES",""))
B11: 9 | C11: LA CEIBA | D11: LC1 - 2 - 5 | E11: 1 | F11: 1 | G11: 2 | H11: 5 | I11: 121 | K11: 30783000 | L11: CEDIDO EN FORMA DE PAGO | N11: =K11 | U11: =IF($D11="","",IF(OR($F11>1,ISNUMBER(SEARCH(" Y ",$D11)),(LEN($D11)-LEN(SUBSTITUTE(UPPER($D11),"LC","")))/2>1),"MÚLTIPLE","INDIVIDUAL")) | V11: =IF($D11="","",IF(AND(ISNUMBER(SEARCH(" Y ",$D11)),$F11<2),"REVISAR # LOTES",""))
B12: 10 | C12: LA CEIBA | D12: LC1 - 2 - 6 | E12: 1 | F12: 1 | G12: 2 | H12: 6 | I12: 170.068 | K12: 43385000 | L12: VENDIDO | M12: NO | N12: =K12 | U12: =IF($D12="","",IF(OR($F12>1,ISNUMBER(SEARCH(" Y ",$D12)),(LEN($D12)-LEN(SUBSTITUTE(UPPER($D12),"LC","")))/2>1),"MÚLTIPLE","INDIVIDUAL")) | V12: =IF($D12="","",IF(AND(ISNUMBER(SEARCH(" Y ",$D12)),$F12<2),"REVISAR # LOTES",""))
B13: 11 | C13: LA CEIBA | D13: LC1 - 2 - 7 | E13: 1 | F13: 1 | G13: 2 | H13: 7 | I13: 98 | K13: 25000000 | L13: VENDIDO | M13: SI | N13: =K13 | U13: =IF($D13="","",IF(OR($F13>1,ISNUMBER(SEARCH(" Y ",$D13)),(LEN($D13)-LEN(SUBSTITUTE(UPPER($D13),"LC","")))/2>1),"MÚLTIPLE","INDIVIDUAL")) | V13: =IF($D13="","",IF(AND(ISNUMBER(SEARCH(" Y ",$D13)),$F13<2),"REVISAR # LOTES",""))
B14: 12 | C14: LA CEIBA | D14: LC1 - 2 - 8 Y 9 | E14: 1 | F14: 2 | G14: 2 | H14: 8 - 9 | I14: 196 | K14: 55000000 | L14: VENDIDO | M14: SI | N14: =K14 | U14: =IF($D14="","",IF(OR($F14>1,ISNUMBER(SEARCH(" Y ",$D14)),(LEN($D14)-LEN(SUBSTITUTE(UPPER($D14),"LC","")))/2>1),"MÚLTIPLE","INDIVIDUAL")) | V14: =IF($D14="","",IF(AND(ISNUMBER(SEARCH(" Y ",$D14)),$F14<2),"REVISAR # LOTES",""))
B15: 13 | C15: LA CEIBA | D15: LC1 - 3 - 1 | E15: 1 | F15: 1 | G15: 3 | H15: 1 | I15: 98 | K15: 30000000 | L15: CEDIDO EN FORMA DE PAGO | N15: =K15 | U15: =IF($D15="","",IF(OR($F15>1,ISNUMBER(SEARCH(" Y ",$D15)),(LEN($D15)-LEN(SUBSTITUTE(UPPER($D15),"LC","")))/2>1),"MÚLTIPLE","INDIVIDUAL")) | V15: =IF($D15="","",IF(AND(ISNUMBER(SEARCH(" Y ",$D15)),$F15<2),"REVISAR # LOTES",""))
B16: 14 | C16: LA CEIBA | D16: LC1 - 3 - 2 | E16: 1 | F16: 1 | G16: 3 | H16: 2 | I16: 98 | K16: 25000000 | L16: EN NEGOCIACIÓN | N16: =K16 | U16: =IF($D16="","",IF(OR($F16>1,ISNUMBER(SEARCH(" Y ",$D16)),(LEN($D16)-LEN(SUBSTITUTE(UPPER($D16),"LC","")))/2>1),"MÚLTIPLE","INDIVIDUAL")) | V16: =IF($D16="","",IF(AND(ISNUMBER(SEARCH(" Y ",$D16)),$F16<2),"REVISAR # LOTES",""))
B17: 15 | C17: LA CEIBA | D17: LC1 - 3 - 3 | E17: 1 | F17: 1 | G17: 3 | H17: 3 | I17: 98 | K17: 25000000 | L17: VENDIDO | M17: SI | N17: =K17 | O17: OK | P17: 46176 | Q17: 9.8e-05 | R17: JOHN ALBERTO BOHORQUEZ | U17: =IF($D17="","",IF(OR($F17>1,ISNUMBER(SEARCH(" Y ",$D17)),(LEN($D17)-LEN(SUBSTITUTE(UPPER($D17),"LC","")))/2>1),"MÚLTIPLE","INDIVIDUAL")) | V17: =IF($D17="","",IF(AND(ISNUMBER(SEARCH(" Y ",$D17)),$F17<2),"REVISAR # LOTES",""))
B18: 16 | C18: LA CEIBA | D18: LC1 - 3 - 4 | E18: 1 | F18: 1 | G18: 3 | H18: 4 | I18: 98 | K18: 25000000 | L18: VENDIDO | M18: SI | N18: =K18 | U18: =IF($D18="","",IF(OR($F18>1,ISNUMBER(SEARCH(" Y ",$D18)),(LEN($D18)-LEN(SUBSTITUTE(UPPER($D18),"LC","")))/2>1),"MÚLTIPLE","INDIVIDUAL")) | V18: =IF($D18="","",IF(AND(ISNUMBER(SEARCH(" Y ",$D18)),$F18<2),"REVISAR # LOTES",""))
B19: 17 | C19: LA CEIBA | D19: LC1 - 3 - 5 | E19: 1 | F19: 1 | G19: 3 | H19: 5 | I19: 98 | K19: 25000000 | L19: VENDIDO | M19: SI | N19: =K19 | U19: =IF($D19="","",IF(OR($F19>1,ISNUMBER(SEARCH(" Y ",$D19)),(LEN($D19)-LEN(SUBSTITUTE(UPPER($D19),"LC","")))/2>1),"MÚLTIPLE","INDIVIDUAL")) | V19: =IF($D19="","",IF(AND(ISNUMBER(SEARCH(" Y ",$D19)),$F19<2),"REVISAR # LOTES",""))
B20: 18 | C20: LA CEIBA | D20: LC1 - 3 - 6 | E20: 1 | F20: 1 | G20: 3 | H20: 6 | I20: 149.2 | K20: 38058000 | L20: VENDIDO | N20: =K20 | U20: =IF($D20="","",IF(OR($F20>1,ISNUMBER(SEARCH(" Y ",$D20)),(LEN($D20)-LEN(SUBSTITUTE(UPPER($D20),"LC","")))/2>1),"MÚLTIPLE","INDIVIDUAL")) | V20: =IF($D20="","",IF(AND(ISNUMBER(SEARCH(" Y ",$D20)),$F20<2),"REVISAR # LOTES",""))
B21: 19 | C21: LA CEIBA | D21: LC1 - 3 - 7 | E21: 1 | F21: 1 | G21: 3 | H21: 7 | I21: 99.8 | K21: 25470000 | L21: DISPONIBLE | N21: =K21 | U21: =IF($D21="","",IF(OR($F21>1,ISNUMBER(SEARCH(" Y ",$D21)),(LEN($D21)-LEN(SUBSTITUTE(UPPER($D21),"LC","")))/2>1),"MÚLTIPLE","INDIVIDUAL")) | V21: =IF($D21="","",IF(AND(ISNUMBER(SEARCH(" Y ",$D21)),$F21<2),"REVISAR # LOTES",""))
B22: 20 | C22: LA CEIBA | D22: LC1 - 3 - 8 | E22: 1 | F22: 1 | G22: 3 | H22: 8 | I22: 98 | K22: 25000000 | L22: DISPONIBLE | N22: =K22 | U22: =IF($D22="","",IF(OR($F22>1,ISNUMBER(SEARCH(" Y ",$D22)),(LEN($D22)-LEN(SUBSTITUTE(UPPER($D22),"LC","")))/2>1),"MÚLTIPLE","INDIVIDUAL")) | V22: =IF($D22="","",IF(AND(ISNUMBER(SEARCH(" Y ",$D22)),$F22<2),"REVISAR # LOTES",""))
B23: 21 | C23: LA CEIBA | D23: LC1 - 3 - 9 | E23: 1 | F23: 1 | G23: 3 | H23: 9 | I23: 99.846 | K23: 25000000 | L23: VENDIDO | M23: NO | N23: =K23 | U23: =IF($D23="","",IF(OR($F23>1,ISNUMBER(SEARCH(" Y ",$D23)),(LEN($D23)-LEN(SUBSTITUTE(UPPER($D23),"LC","")))/2>1),"MÚLTIPLE","INDIVIDUAL")) | V23: =IF($D23="","",IF(AND(ISNUMBER(SEARCH(" Y ",$D23)),$F23<2),"REVISAR # LOTES",""))
B24: 22 | C24: LA CEIBA | D24: LC1 - 3 - 10 Y 11 | E24: 1 | F24: 2 | G24: 3 | H24: 10 - 11 | I24: 196 | K24: 50000000 | L24: VENDIDO | M24: NO | N24: =K24 | U24: =IF($D24="","",IF(OR($F24>1,ISNUMBER(SEARCH(" Y ",$D24)),(LEN($D24)-LEN(SUBSTITUTE(UPPER($D24),"LC","")))/2>1),"MÚLTIPLE","INDIVIDUAL")) | V24: =IF($D24="","",IF(AND(ISNUMBER(SEARCH(" Y ",$D24)),$F24<2),"REVISAR # LOTES",""))
B25: 23 | C25: LA CEIBA | D25: LC1 - 3 - 12 | E25: 1 | F25: 1 | G25: 3 | H25: 12 | I25: 98 | K25: 30000000 | L25: CEDIDO EN FORMA DE PAGO | N25: =K25 | U25: =IF($D25="","",IF(OR($F25>1,ISNUMBER(SEARCH(" Y ",$D25)),(LEN($D25)-LEN(SUBSTITUTE(UPPER($D25),"LC","")))/2>1),"MÚLTIPLE","INDIVIDUAL")) | V25: =IF($D25="","",IF(AND(ISNUMBER(SEARCH(" Y ",$D25)),$F25<2),"REVISAR # LOTES",""))
B26: 24 | C26: LA CEIBA | D26: LC1 - 4 - 1 | E26: 1 | F26: 1 | G26: 4 | H26: 1 | I26: 150.4 | K26: 43380000 | L26: VENDIDO | N26: =K26 | U26: =IF($D26="","",IF(OR($F26>1,ISNUMBER(SEARCH(" Y ",$D26)),(LEN($D26)-LEN(SUBSTITUTE(UPPER($D26),"LC","")))/2>1),"MÚLTIPLE","INDIVIDUAL")) | V26: =IF($D26="","",IF(AND(ISNUMBER(SEARCH(" Y ",$D26)),$F26<2),"REVISAR # LOTES",""))
B27: 25 | C27: LA CEIBA | D27: LC1 - 4 - 2 | E27: 1 | F27: 1 | G27: 4 | H27: 2 | I27: 140.999 | K27: 35970000 | L27: VENDIDO | M27: SI | N27: =K27 | U27: =IF($D27="","",IF(OR($F27>1,ISNUMBER(SEARCH(" Y ",$D27)),(LEN($D27)-LEN(SUBSTITUTE(UPPER($D27),"LC","")))/2>1),"MÚLTIPLE","INDIVIDUAL")) | V27: =IF($D27="","",IF(AND(ISNUMBER(SEARCH(" Y ",$D27)),$F27<2),"REVISAR # LOTES",""))
B28: 26 | C28: LA CEIBA | D28: LC1 - 4 - 3 | E28: 1 | F28: 1 | G28: 4 | H28: 3 | I28: 130.981 | K28: 33413000 | L28: VENDIDO | M28: SI | N28: =K28 | U28: =IF($D28="","",IF(OR($F28>1,ISNUMBER(SEARCH(" Y ",$D28)),(LEN($D28)-LEN(SUBSTITUTE(UPPER($D28),"LC","")))/2>1),"MÚLTIPLE","INDIVIDUAL")) | V28: =IF($D28="","",IF(AND(ISNUMBER(SEARCH(" Y ",$D28)),$F28<2),"REVISAR # LOTES",""))
B29: 27 | C29: LA CEIBA | D29: LC1 - 4 - 4 | E29: 1 | F29: 1 | G29: 4 | H29: 4 | I29: 120.928 | K29: 30849000 | L29: VENDIDO | M29: SI | N29: =K29 | U29: =IF($D29="","",IF(OR($F29>1,ISNUMBER(SEARCH(" Y ",$D29)),(LEN($D29)-LEN(SUBSTITUTE(UPPER($D29),"LC","")))/2>1),"MÚLTIPLE","INDIVIDUAL")) | V29: =IF($D29="","",IF(AND(ISNUMBER(SEARCH(" Y ",$D29)),$F29<2),"REVISAR # LOTES",""))
B30: 28 | C30: LA CEIBA | D30: LC1 - 4 - 5 | E30: 1 | F30: 1 | G30: 4 | H30: 5 | I30: 110.8 | K30: 28276000 | L30: VENDIDO | N30: =K30 | U30: =IF($D30="","",IF(OR($F30>1,ISNUMBER(SEARCH(" Y ",$D30)),(LEN($D30)-LEN(SUBSTITUTE(UPPER($D30),"LC","")))/2>1),"MÚLTIPLE","INDIVIDUAL")) | V30: =IF($D30="","",IF(AND(ISNUMBER(SEARCH(" Y ",$D30)),$F30<2),"REVISAR # LOTES",""))
B31: 29 | C31: LA CEIBA | D31: LC1 - 4 - 6 | E31: 1 | F31: 1 | G31: 4 | H31: 6 | I31: 98.223 | K31: 25056000 | L31: VENDIDO | M31: NO | N31: =K31 | U31: =IF($D31="","",IF(OR($F31>1,ISNUMBER(SEARCH(" Y ",$D31)),(LEN($D31)-LEN(SUBSTITUTE(UPPER($D31),"LC","")))/2>1),"MÚLTIPLE","INDIVIDUAL")) | V31: =IF($D31="","",IF(AND(ISNUMBER(SEARCH(" Y ",$D31)),$F31<2),"REVISAR # LOTES",""))
B32: 30 | C32: LA CEIBA | D32: LC1 - 4 - 7 | E32: 1 | F32: 1 | G32: 4 | H32: 7 | I32: 95.303 | K32: 25000000 | L32: VENDIDO | M32: NO | N32: =K32 | U32: =IF($D32="","",IF(OR($F32>1,ISNUMBER(SEARCH(" Y ",$D32)),(LEN($D32)-LEN(SUBSTITUTE(UPPER($D32),"LC","")))/2>1),"MÚLTIPLE","INDIVIDUAL")) | V32: =IF($D32="","",IF(AND(ISNUMBER(SEARCH(" Y ",$D32)),$F32<2),"REVISAR # LOTES",""))
B33: 31 | C33: LA CEIBA | D33: LC1- 5 - 1 | E33: 1 | F33: 1 | G33: 5 | H33: 1 | I33: 162.2 | K33: 41380000 | L33: VENDIDO | N33: =K33 | U33: =IF($D33="","",IF(OR($F33>1,ISNUMBER(SEARCH(" Y ",$D33)),(LEN($D33)-LEN(SUBSTITUTE(UPPER($D33),"LC","")))/2>1),"MÚLTIPLE","INDIVIDUAL")) | V33: =IF($D33="","",IF(AND(ISNUMBER(SEARCH(" Y ",$D33)),$F33<2),"REVISAR # LOTES",""))
B34: 32 | C34: LA CEIBA | D34: LC1 - 5 - 2 | E34: 1 | F34: 1 | G34: 5 | H34: 2 | I34: 98 | K34: 25000000 | L34: VENDIDO | M34: SI | N34: =K34 | U34: =IF($D34="","",IF(OR($F34>1,ISNUMBER(SEARCH(" Y ",$D34)),(LEN($D34)-LEN(SUBSTITUTE(UPPER($D34),"LC","")))/2>1),"MÚLTIPLE","INDIVIDUAL")) | V34: =IF($D34="","",IF(AND(ISNUMBER(SEARCH(" Y ",$D34)),$F34<2),"REVISAR # LOTES",""))
B35: 33 | C35: LA CEIBA | D35: LC1 - 5 - 3 | E35: 1 | F35: 1 | G35: 5 | H35: 3 | I35: 98 | K35: 30000000 | L35: VENDIDO | M35: SI | N35: =K35 | U35: =IF($D35="","",IF(OR($F35>1,ISNUMBER(SEARCH(" Y ",$D35)),(LEN($D35)-LEN(SUBSTITUTE(UPPER($D35),"LC","")))/2>1),"MÚLTIPLE","INDIVIDUAL")) | V35: =IF($D35="","",IF(AND(ISNUMBER(SEARCH(" Y ",$D35)),$F35<2),"REVISAR # LOTES",""))
B36: 34 | C36: LA CEIBA | D36: LC1 - 5 - 4 | E36: 1 | F36: 1 | G36: 5 | H36: 4 | I36: 98 | K36: 30000000 | L36: VENDIDO | M36: SI | N36: =K36 | U36: =IF($D36="","",IF(OR($F36>1,ISNUMBER(SEARCH(" Y ",$D36)),(LEN($D36)-LEN(SUBSTITUTE(UPPER($D36),"LC","")))/2>1),"MÚLTIPLE","INDIVIDUAL")) | V36: =IF($D36="","",IF(AND(ISNUMBER(SEARCH(" Y ",$D36)),$F36<2),"REVISAR # LOTES",""))
B37: 35 | C37: LA CEIBA | D37: LC1 - 5 - 5 | E37: 1 | F37: 1 | G37: 5 | H37: 5 | I37: 98 | K37: 25000000 | L37: VENDIDO | M37: SI | N37: =K37 | O37: OK | Q37: 0.0098 | R37: RUBEN FABIAN BUSTOS | U37: =IF($D37="","",IF(OR($F37>1,ISNUMBER(SEARCH(" Y ",$D37)),(LEN($D37)-LEN(SUBSTITUTE(UPPER($D37),"LC","")))/2>1),"MÚLTIPLE","INDIVIDUAL")) | V37: =IF($D37="","",IF(AND(ISNUMBER(SEARCH(" Y ",$D37)),$F37<2),"REVISAR # LOTES",""))
B38: 36 | C38: LA CEIBA | D38: LC1 - 5 - 6 | E38: 1 | F38: 1 | G38: 5 | H38: 6 | I38: 131.484 | K38: 33541000 | L38: VENDIDO | M38: NO | N38: =K38 | U38: =IF($D38="","",IF(OR($F38>1,ISNUMBER(SEARCH(" Y ",$D38)),(LEN($D38)-LEN(SUBSTITUTE(UPPER($D38),"LC","")))/2>1),"MÚLTIPLE","INDIVIDUAL")) | V38: =IF($D38="","",IF(AND(ISNUMBER(SEARCH(" Y ",$D38)),$F38<2),"REVISAR # LOTES",""))
B39: 37 | C39: LA CEIBA | D39: LC1 - 6 - 1 | E39: 1 | F39: 1 | G39: 6 | H39: 1 | I39: 98 | K39: 30000000 | L39: VENDIDO | M39: NO | N39: =K39 | U39: =IF($D39="","",IF(OR($F39>1,ISNUMBER(SEARCH(" Y ",$D39)),(LEN($D39)-LEN(SUBSTITUTE(UPPER($D39),"LC","")))/2>1),"MÚLTIPLE","INDIVIDUAL")) | V39: =IF($D39="","",IF(AND(ISNUMBER(SEARCH(" Y ",$D39)),$F39<2),"REVISAR # LOTES",""))
B40: 38 | C40: LA CEIBA | D40: LC1 - 6 - 2 | E40: 1 | F40: 1 | G40: 6 | H40: 2 | I40: 98 | K40: 25000000 | L40: VENDIDO | M40: SI | N40: =K40 | U40: =IF($D40="","",IF(OR($F40>1,ISNUMBER(SEARCH(" Y ",$D40)),(LEN($D40)-LEN(SUBSTITUTE(UPPER($D40),"LC","")))/2>1),"MÚLTIPLE","INDIVIDUAL")) | V40: =IF($D40="","",IF(AND(ISNUMBER(SEARCH(" Y ",$D40)),$F40<2),"REVISAR # LOTES",""))
...

Sheet VENTAS
A2: ITEM | B2: ID LOTE | C2: ESTADO | D2: PRECIO DE VENTA | E2: APARTADOS | F2: FECHA DE VENTA | G2: VALOR CUOTA INICIAL | H2: FECHA DE PAGO DE LA CUOTA INICIAL | I2: MEDIO DE PAGO | J2: SALDO FINANCIADO | K2: PLAZO/CUOTAS | L2: VALOR CUOTA | M2: DIAS DE PAGO | N2: # DOC CLIENTE | O2: NOMBRE Y APELLIDOS | P2: CELULAR | Q2: DIRECCIÓN | R2: CIUDAD | T2: COMISIÓN VENDEDOR | U2: ABONOS | V2: DESCUENTOS | W2: SALDO
A3: =LISTADO!B3 | B3: =LISTADO!D3 | C3: =LISTADO!L3 | D3: =LISTADO!K3 | J3: =D3-G3 | W3: =T3-U3-V3
A4: =LISTADO!B4 | B4: =LISTADO!D4 | C4: =LISTADO!L4 | D4: =LISTADO!K4 | F4: 45839 | G4: 8000000 | H4: 45870 | I4: EFECTIVO | J4: =D4-G4 | K4: 24 | L4: =J4/K4 | M4: 01 DE CADA MES | N4: 52466375 | O4: ANA MILENA CHAVES/JOSE IGNACIO DIAZ | P4: 311 5303163 | R4: BOGOTA | S4: SNEIDER | T4: 10000000 | U4: 6000000 | W4: =T4-U4-V4
A5: =LISTADO!B5 | B5: =LISTADO!D5 | C5: =LISTADO!L5 | D5: =LISTADO!K5 | F5: 45890 | G5: 4000000 | H5: 45921 | I5: EFECTIVO | J5: =D5-G5 | K5: 24 | L5: =J5/K5 | M5: 21 DE CADA MES | N5: 46645364 | O5: MARIA EUGENIA RIOS/ARTURO CARRILLO MEJIA | P5: 316 3162386 | R5: BOYACA | S5: SNEIDER | T5: 5000000 | U5: 5000000 | W5: =T5-U5-V5
A6: =LISTADO!B6 | B6: =LISTADO!D6 | C6: =LISTADO!L6 | D6: =LISTADO!K6 | F6: 46002 | G6: 5400000 | H6: 46033 | I6: EFECTIVO | J6: =D6-G6 | K6: 24 | L6: =J6/K6 | M6: 11 DE CADA MES | N6: 1000001654 | O6: FREDY LEANDRO CASTRO DULCEY | P6: 300 5655877 | R6: BOGOTA | S6: DANIEL BARRETO | T6: 5000000 | U6: 3000000 | W6: =T6-U6-V6
A7: =LISTADO!B7 | B7: =LISTADO!D7 | C7: =LISTADO!L7 | D7: =LISTADO!K7 | F7: 45845 | G7: 4000000 | H7: 45876 | I7: EFECTIVO | J7: =D7-G7 | K7: 24 | L7: =J7/K7 | M7: 07 DE CADA MES | N7: 1016011597 | O7: DIVIANGI PAOLA LARREA AVILA | P7: 320 3658707 | R7: BOGOTA | S7: YURANY PEREZ | T7: 5000000 | U7: 3000000 | W7: =T7-U7-V7
A8: =LISTADO!B8 | B8: =LISTADO!D8 | C8: =LISTADO!L8 | D8: =LISTADO!K8 | F8: 45855 | G8: 4000000 | H8: 45886 | I8: EFECTIVO | J8: =D8-G8 | K8: 24 | L8: =J8/K8 | M8: 17 DE CADA MES | N8: 1065606738 | O8: DIANA CAROLINA SANTIAGO BELLO | P8: 324 4168643 | R8: BOGOTA | S8: DANIA | T8: 5000000 | U8: 3000000 | W8: =T8-U8-V8
A9: =LISTADO!B9 | B9: =LISTADO!D9 | C9: =LISTADO!L9 | D9: =LISTADO!K9 | J9: =D9-G9 | K9: 1 | L9: =J9/K9 | O9: RUBEN FABIAN BUSTOS | W9: =T9-U9-V9
A10: =LISTADO!B10 | B10: =LISTADO!D10 | C10: =LISTADO!L10 | D10: =LISTADO!K10 | J10: =D10-G10 | K10: 1 | L10: =J10/K10 | O10: RUBEN FABIAN BUSTOS | W10: =T10-U10-V10
A11: =LISTADO!B11 | B11: =LISTADO!D11 | C11: =LISTADO!L11 | D11: =LISTADO!K11 | J11: =D11-G11 | K11: 1 | L11: =J11/K11 | O11: RUBEN FABIAN BUSTOS | W11: =T11-U11-V11
A12: =LISTADO!B12 | B12: =LISTADO!D12 | C12: =LISTADO!L12 | D12: =LISTADO!K12 | F12: 46041 | G12: 4000000 | H12: 46072 | I12: EFECTIVO | J12: =D12-G12 | K12: 24 | L12: =J12/K12 | M12: 19 DE CADA MES | N12: 51803549 | O12: MARTHA EUGENIA OCAMPO GOMEZ | P12: 3223810013 | R12: ACACIAS | S12: KATHERINE TACHA | T12: 5000000 | U12: 3000000 | W12: =T12-U12-V12
A13: =LISTADO!B13 | B13: =LISTADO!D13 | C13: =LISTADO!L13 | D13: =LISTADO!K13 | F13: 45855 | G13: 4000000 | H13: 45886 | I13: EFECTIVO | J13: =D13-G13 | K13: 24 | L13: =J13/K13 | M13: 17 DE CADA MES | N13: 49595489 | O13: JOSSY XIMENA CASTELLANOS CARRILLO | P13: 305 4524007 | R13: BOSCONIA | S13: DANIA | T13: 5000000 | U13: 3000000 | W13: =T13-U13-V13
A14: =LISTADO!B14 | B14: =LISTADO!D14 | C14: =LISTADO!L14 | D14: =LISTADO!K14 | F14: 45865 | G14: 8000000 | H14: 45896 | I14: EFECTIVO | J14: =D14-G14 | K14: 24 | L14: =J14/K14 | M14: 27 DE CADA MES | N14: 36622525 | O14: BETTY ENCARNACION CARRILLO | P14: 304 5900648 | R14: ACACIAS | S14: DANIA | T14: 10000000 | U14: 6000000 | W14: =T14-U14-V14
A15: =LISTADO!B15 | B15: =LISTADO!D15 | C15: =LISTADO!L15 | D15: =LISTADO!K15 | J15: =D15-G15 | K15: 1 | L15: =J15/K15 | O15: RUBEN FABIAN BUSTO | W15: =T15-U15-V15
A16: =LISTADO!B16 | B16: =LISTADO!D16 | C16: =LISTADO!L16 | D16: =LISTADO!K16 | J16: =D16-G16 | L16: =J16/K16 | W16: =T16-U16-V16
A17: =LISTADO!B17 | B17: =LISTADO!D17 | C17: =LISTADO!L17 | D17: =LISTADO!K17 | F17: 45936 | G17: 4000000 | H17: 45967 | I17: EFECTIVO | J17: =D17-G17 | K17: 24 | L17: =J17/K17 | M17: 06 DE CADA MES | N17: 7182722 | O17: EDGAR VICENTE CARDENAS LOPEZ | P17: 313 2213086 | R17: TUNJA | S17: JHON JAIRO RINCON | T17: 5000000 | U17: 3000000 | W17: =T17-U17-V17
A18: =LISTADO!B18 | B18: =LISTADO!D18 | C18: =LISTADO!L18 | D18: =LISTADO!K18 | F18: 46102 | G18: 4000000 | H18: 46086 | I18: EFECTIVO | J18: =D18-G18 | K18: 24 | L18: =J18/K18 | M18: 05 DE CADA MES | N18: 41627694 | O18: RAQUEL ABELLA VALBUENA | P18: 316 3901345 | R18: BOGOTA | S18: GUSTAVO | T18: 5000000 | U18: 3000000 | W18: =T18-U18-V18
A19: =LISTADO!B19 | B19: =LISTADO!D19 | C19: =LISTADO!L19 | D19: =LISTADO!K19 | F19: 46102 | G19: 4000000 | H19: 46086 | I19: EFECTIVO | J19: =D19-G19 | K19: 24 | L19: =J19/K19 | M19: 05 DE CADA MES | N19: 41627694 | O19: RAQUEL ABELLA VALBUENA | P19: 316 3901345 | R19: BOGOTA | S19: GUSTAVO | T19: 5000000 | U19: 3000000 | W19: =T19-U19-V19
A20: =LISTADO!B20 | B20: =LISTADO!D20 | C20: =LISTADO!L20 | D20: =LISTADO!K20 | F20: 46128 | G20: 4000000 | H20: 46128 | I20: TRANSFERENCIA | J20: =D20-G20 | K20: 24 | L20: =J20/K20 | M20: 16 DE CADA MES | N20: 1026277934 | O20: SAMANTA VALENSUELA BARRAZA | S20: YURANY PEREZ | T20: 5000000 | W20: =T20-U20-V20
A21: =LISTADO!B21 | B21: =LISTADO!D21 | C21: =LISTADO!L21 | D21: =LISTADO!K21 | J21: =D21-G21 | L21: =J21/K21 | W21: =T21-U21-V21
A22: =LISTADO!B22 | B22: =LISTADO!D22 | C22: =LISTADO!L22 | D22: =LISTADO!K22 | J22: =D22-G22 | L22: =J22/K22 | W22: =T22-U22-V22
A23: =LISTADO!B23 | B23: =LISTADO!D23 | C23: =LISTADO!L23 | D23: =LISTADO!K23 | F23: 45920 | G23: 4000000 | H23: 45950 | I23: EFECTIVO | J23: =D23-G23 | K23: 24 | L23: =J23/K23 | M23: 20 DE CADA MES | N23: 1121947747 | O23: LUISA FERNANDA GOMEZ CARRERO/JUAN DAVID REY | P23: 310 6673835 | R23: VILLAVICENCIO | S23: INGRID | T23: 5000000 | U23: 3000000 | W23: =T23-U23-V23
A24: =LISTADO!B24 | B24: =LISTADO!D24 | C24: =LISTADO!L24 | D24: =LISTADO!K24 | F24: 45902 | G24: 8000000 | H24: 45932 | I24: EFECTIVO | J24: =D24-G24 | K24: 24 | L24: =J24/K24 | M24: 02 DE CADA MES | N24: 26203383 | O24: FATIMA RAMIREZ MORALES | P24: 313 22006339 | R24: MONTERIA | S24: DANIA | T24: 10000000 | U24: 6000000 | W24: =T24-U24-V24
A25: =LISTADO!B25 | B25: =LISTADO!D25 | C25: =LISTADO!L25 | D25: =LISTADO!K25 | J25: =D25-G25 | L25: =J25/K25 | O25: RUBEN FABIAN BUSTOS | W25: =T25-U25-V25
A26: =LISTADO!B26 | B26: =LISTADO!D26 | C26: =LISTADO!L26 | D26: =LISTADO!K26 | F26: 46178 | G26: 4000000 | H26: 46178 | I26: TRANSFERENCIA | J26: 39380000 | K26: 24 | L26: =J26/K26 | M26: 5 DE CADA MES | N26: 51648764 | O26: MARIA YOLANDA CARACAS LEÓN | P26: 321 4612934 | S26: JEFFERSON | T26: 5000000 | U26: 3000000 | W26: =T26-U26-V26
A27: =LISTADO!B27 | B27: =LISTADO!D27 | C27: =LISTADO!L27 | D27: =LISTADO!K27 | F27: 30/02/2026 | G27: 8000000 | H27: 46111 | I27: EFECTIVO | J27: =D27-G27 | K27: 30 | L27: =J27/K27 | M27: 30 DE CADA MES | N27: 1007157001 | O27: LEIDY JOHANNA SAENZ/JHOJAN STIVEN GUTIERREZ | P27: 301 2669937 | R27: BOGOTA | S27: INGRID | T27: 5000000 | U27: 3000000 | W27: =T27-U27-V27
A28: =LISTADO!B28 | B28: =LISTADO!D28 | C28: =LISTADO!L28 | D28: =LISTADO!K28 | F28: 46063 | G28: 9000000 | H28: 46091 | I28: EFECTIVO | J28: =D28-G28 | K28: 30 | L28: =J28/K28 | M28: 10 DE CADA MES | N28: 41795576 | O28: AURA ALICIA SAENZ | P28: 312 3756562 | R28: BOGOTA | S28: INGRID | T28: 5000000 | U28: 3000000 | W28: =T28-U28-V28
A29: =LISTADO!B29 | B29: =LISTADO!D29 | C29: =LISTADO!L29 | D29: =LISTADO!K29 | F29: 46060 | G29: 13000000 | H29: 46088 | I29: EFECTIVO | J29: =D29-G29 | K29: 30 | L29: =J29/K29 | M29: 07 DE CADA MES | N29: 1007157000 | O29: EDUINXON ALEXANDER SAENZ PINZON | P29: 301 7284433 | R29: BOGOTA | S29: INGRID | T29: 5000000 | U29: 3000000 | W29: =T29-U29-V29
A30: =LISTADO!B30 | B30: =LISTADO!D30 | C30: =LISTADO!L30 | D30: =LISTADO!K30 | J30: =D30-G30 | K30: 1 | L30: =J30/K30 | N30: 80390046 | O30: JORGE HUMBERTO RODRIGUEZ BORBON | W30: =T30-U30-V30
A31: =LISTADO!B31 | B31: =LISTADO!D31 | C31: =LISTADO!L31 | D31: =LISTADO!K31 | F31: 46031 | G31: 4000000 | H31: 46062 | I31: EFECTIVO | J31: =D31-G31 | K31: 24 | L31: =J31/K31 | M31: 09 DE CADA MES | N31: 51578847 | O31: LUZ MYRIAM DÍAZ | P31: 312 3492087 | R31: BOGOTA | S31: LUBIN DIAZ | T31: 5000000 | U31: 3000000 | W31: =T31-U31-V31
A32: =LISTADO!B32 | B32: =LISTADO!D32 | C32: =LISTADO!L32 | D32: =LISTADO!K32 | F32: 46031 | G32: 4500000 | H32: 46062 | I32: EFECTIVO | J32: =D32-G32 | K32: 24 | L32: =J32/K32 | M32: 09 DE CADA MES | N32: 1085039584 | O32: ALEXIS JOSE PABA MARTINEZ | P32: 34 62419 4900 | R32: EL BANCO | S32: LUBIN DIAZ | T32: 5000000 | U32: 3000000 | W32: =T32-U32-V32
A33: =LISTADO!B33 | B33: =LISTADO!D33 | C33: =LISTADO!L33 | D33: =LISTADO!K33 | F33: 46150 | G33: 4000000 | H33: 46150 | I33: TRANSFERENCIA | J33: =D33-G33 | K33: 24 | L33: =J33/K33 | M33: 30 DE CADA MES | N33: 1024499636 | O33: DANNA LIZETH ALVAREZ SANCHEZ | P33: 310 240 1772 | R33: CUNDINAMARCA | S33: YURANY PEREZ | T33: 5000000 | W33: =T33-U33-V33
A34: =LISTADO!B34 | B34: =LISTADO!D34 | C34: =LISTADO!L34 | D34: =LISTADO!K34 | F34: 45701 | G34: 4000000 | H34: 45729 | I34: EFECTIVO | J34: =D34-G34 | K34: 24 | L34: =J34/K34 | M34: 13 DE CADA MES | N34: 1015408595 | O34: LUIS AGUSTO PALACIOS RODRIGUEZ | P34: 3228636376 | R34: BOGOTA | W34: =T34-U34-V34
A35: =LISTADO!B35 | B35: =LISTADO!D35 | C35: =LISTADO!L35 | D35: =LISTADO!K35 | F35: 45874 | G35: 4500000 | H35: 45905 | I35: EFECTIVO | J35: =D35-G35 | K35: 24 | L35: =J35/K35 | M35: 05 DE CADA MES | N35: 1012356817 | O35: YULEY SERRANO PAVA/DIEGO FERNANDO BUITRAGO | P35: 311 2085098 | R35: BOGOTA | S35: JHON CARVAJAL | T35: 5000000 | U35: 3000000 | W35: =T35-U35-V35
A36: =LISTADO!B36 | B36: =LISTADO!D36 | C36: =LISTADO!L36 | D36: =LISTADO!K36 | F36: 45874 | G36: 4500000 | H36: 45905 | I36: EFECTIVO | J36: =D36-G36 | K36: 24 | L36: =J36/K36 | M36: 05 DE CADA MES | N36: 1030701120 | O36: ANDRÉS FELIPE CARDONA ARCHILA | P36: 315 4450034 | R36: BOGOTA | S36: MAYERLY | T36: 5000000 | U36: 3000000 | W36: =T36-U36-V36
A37: =LISTADO!B37 | B37: =LISTADO!D37 | C37: =LISTADO!L37 | D37: =LISTADO!K37 | F37: 45874 | G37: 7500000 | H37: 45905 | I37: EFECTIVO | J37: =D37-G37 | K37: 24 | L37: =J37/K37 | M37: 05 DE CADA MES | N37: 1123433099 | O37: JEIDER HERNEY POVEDA ROSO | P37: 3195907896 | R37: CASTILLA LA NUEVA | S37: YULIAN CARDENAS | T37: 5000000 | U37: 5000000 | W37: =T37-U37-V37
A38: =LISTADO!B38 | B38: =LISTADO!D38 | C38: =LISTADO!L38 | D38: =LISTADO!K38 | F38: 46073 | G38: 4000000 | H38: 46101 | I38: EFECTIVO | J38: =D38-G38 | K38: 24 | L38: =J38/K38 | M38: 20 DE CADA MES | N38: 1123085644 | O38: MILENA JOHANNA COCA MEJIA/YEISON ALBERTO MONROY | P38: 313 3458707 | R38: GUAMAL | S38: YURANY PEREZ | T38: 5000000 | U38: 3000000 | W38: =T38-U38-V38
A39: =LISTADO!B39 | B39: =LISTADO!D39 | C39: =LISTADO!L39 | D39: =LISTADO!K39 | F39: 45842 | G39: 4000000 | H39: 45873 | I39: EFECTIVO | J39: =D39-G39 | K39: 24 | L39: =J39/K39 | M39: 04 DE CADA MES | N39: 1003519576 | O39: YARID MARIANA MONROY VIVAS | P39: 704 2989061 | R39: FUSAGASUGA | S39: CARLOS JULIAN | T39: 5000000 | U39: 3000000 | W39: =T39-U39-V39
A40: =LISTADO!B40 | B40: =LISTADO!D40 | C40: =LISTADO!L40 | D40: =LISTADO!K40 | F40: 45888 | G40: 10000000 | H40: 45919 | I40: EFECTIVO | J40: =D40-G40 | K40: 24 | L40: =J40/K40 | M40: 19 DE CADA MES | N40: 4157914 | O40: LUIS ENRIQUE ALARCON CRUZ | P40: 316 3355530 | R40: BOYACA | S40: YULIAN CARDENAS | T40: 5000000 | U40: 3000000 | W40: =T40-U40-V40
A41: =LISTADO!B41 | B41: =LISTADO!D41 | C41: =LISTADO!L41 | D41: =LISTADO!K41 | F41: 45656 | G41: 4000000 | H41: 45687 | I41: EFECTIVO | J41: =D41-G41 | K41: 24 | L41: =J41/K41 | M41: 30 DE CADA MES | N41: 86011972 | O41: JOSÉ ALCIDES QUINTERO GAITAN | P41: 322 2458447 | R41: GRANADA | W41: =T41-U41-V41
...

Sheet PROYECCIÓN
K2: CUOTA 1 | L2: CUOTA 1 | M2: CUOTA 1 | N2: CUOTA 1 | O2: CUOTA 1 | P2: CUOTA 1 | Q2: CUOTA 2 | R2: CUOTA 2 | S2: CUOTA 2 | T2: CUOTA 2 | U2: CUOTA 2 | V2: CUOTA 2 | W2: CUOTA 3 | X2: CUOTA 3 | Y2: CUOTA 3 | Z2: CUOTA 3 | AA2: CUOTA 3 | AB2: CUOTA 3 | AC2: CUOTA 4 | AD2: CUOTA 4 | AE2: CUOTA 4 | AF2: CUOTA 4 | AG2: CUOTA 4 | AH2: CUOTA 4 | AI2: CUOTA 5 | AJ2: CUOTA 5 | AK2: CUOTA 5 | AL2: CUOTA 5 | AM2: CUOTA 5 | AN2: CUOTA 5 | AO2: CUOTA 6 | AP2: CUOTA 6 | AQ2: CUOTA 6 | AR2: CUOTA 6 | AS2: CUOTA 6 | AT2: CUOTA 6 | AU2: CUOTA 7 | AV2: CUOTA 7 | AW2: CUOTA 7 | AX2: CUOTA 7 | AY2: CUOTA 7 | AZ2: CUOTA 7 | BA2: CUOTA 8 | BB2: CUOTA 8 | BC2: CUOTA 8 | BD2: CUOTA 8 | BE2: CUOTA 8 | BF2: CUOTA 8 | BG2: CUOTA 9 | BH2: CUOTA 9 | BI2: CUOTA 9 | BJ2: CUOTA 9 | BK2: CUOTA 9 | BL2: CUOTA 9 | BM2: CUOTA 10 | BN2: CUOTA 10 | BO2: CUOTA 10 | BP2: CUOTA 10 | BQ2: CUOTA 10 | BR2: CUOTA 10 | BS2: CUOTA 11 | BT2: CUOTA 11 | BU2: CUOTA 11 | BV2: CUOTA 11 | BW2: CUOTA 11 | BX2: CUOTA 11 | BY2: CUOTA 12 | BZ2: CUOTA 12 | CA2: CUOTA 12 | CB2: CUOTA 12 | CC2: CUOTA 12 | CD2: CUOTA 12 | CE2: CUOTA 13 | CF2: CUOTA 13 | CG2: CUOTA 13 | CH2: CUOTA 13 | CI2: CUOTA 13 | CJ2: CUOTA 13 | CK2: CUOTA 14 | CL2: CUOTA 14 | CM2: CUOTA 14 | CN2: CUOTA 14 | CO2: CUOTA 14 | CP2: CUOTA 14 | CQ2: CUOTA 15 | CR2: CUOTA 15 | CS2: CUOTA 15 | CT2: CUOTA 15 | CU2: CUOTA 15 | CV2: CUOTA 15 | CW2: CUOTA 16 | CX2: CUOTA 16 | CY2: CUOTA 16 | CZ2: CUOTA 16 | DA2: CUOTA 16 | DB2: CUOTA 16 | DC2: CUOTA 17 | DD2: CUOTA 17 | DE2: CUOTA 17 | DF2: CUOTA 17 | DG2: CUOTA 17 | DH2: CUOTA 17 | DI2: CUOTA 18 | DJ2: CUOTA 18 | DK2: CUOTA 18 | DL2: CUOTA 18 | DM2: CUOTA 18 | DN2: CUOTA 18 | DO2: CUOTA 19 | DP2: CUOTA 19 | DQ2: CUOTA 19 | DR2: CUOTA 19 | DS2: CUOTA 19 | DT2: CUOTA 19 | DU2: CUOTA 20 | DV2: CUOTA 20 | DW2: CUOTA 20 | DX2: CUOTA 20 | DY2: CUOTA 20 | DZ2: CUOTA 20 | EA2: CUOTA 21 | EB2: CUOTA 21 | EC2: CUOTA 21 | ED2: CUOTA 21 | EE2: CUOTA 21 | EF2: CUOTA 21 | EG2: CUOTA 22 | EH2: CUOTA 22 | EI2: CUOTA 22 | EJ2: CUOTA 22 | EK2: CUOTA 22 | EL2: CUOTA 22 | EM2: CUOTA 23 | EN2: CUOTA 23 | EO2: CUOTA 23 | EP2: CUOTA 23 | EQ2: CUOTA 23 | ER2: CUOTA 23 | ES2: CUOTA 24 | ET2: CUOTA 24 | EU2: CUOTA 24 | EV2: CUOTA 24 | EW2: CUOTA 24 | EX2: CUOTA 24 | EY2: CUOTA 25 | EZ2: CUOTA 25 | FA2: CUOTA 25 | FB2: CUOTA 25 | FC2: CUOTA 25 | FD2: CUOTA 25 | FE2: CUOTA 26 | FF2: CUOTA 26 | FG2: CUOTA 26 | FH2: CUOTA 26 | FI2: CUOTA 26 | FJ2: CUOTA 26 | FK2: CUOTA 27 | FL2: CUOTA 27 | FM2: CUOTA 27 | FN2: CUOTA 27 | FO2: CUOTA 27 | FP2: CUOTA 27 | FQ2: CUOTA 28 | FR2: CUOTA 28 | FS2: CUOTA 28 | FT2: CUOTA 28 | FU2: CUOTA 28 | FV2: CUOTA 28 | FW2: CUOTA 29 | FX2: CUOTA 29 | FY2: CUOTA 29 | FZ2: CUOTA 29 | GA2: CUOTA 29 | GB2: CUOTA 29 | GC2: CUOTA 30 | GD2: CUOTA 30 | GE2: CUOTA 30 | GF2: CUOTA 30 | GG2: CUOTA 30 | GH2: CUOTA 30 | GI2: CUOTA 31 | GJ2: CUOTA 31 | GK2: CUOTA 31 | GL2: CUOTA 31 | GM2: CUOTA 31 | GN2: CUOTA 31 | GO2: CUOTA 32 | GP2: CUOTA 32 | GQ2: CUOTA 32 | GR2: CUOTA 32 | GS2: CUOTA 32 | GT2: CUOTA 32 | GU2: CUOTA 33 | GV2: CUOTA 33 | GW2: CUOTA 33 | GX2: CUOTA 33 | GY2: CUOTA 33 | GZ2: CUOTA 33 | HA2: CUOTA 34 | HB2: CUOTA 34 | HC2: CUOTA 34 | HD2: CUOTA 34 | HE2: CUOTA 34 | HF2: CUOTA 34 | HG2: CUOTA 35 | HH2: CUOTA 35 | HI2: CUOTA 35 | HJ2: CUOTA 35 | HK2: CUOTA 35 | HL2: CUOTA 35 | HM2: CUOTA 36 | HN2: CUOTA 36 | HO2: CUOTA 36 | HP2: CUOTA 36 | HQ2: CUOTA 36 | HR2: CUOTA 36
B3: ITEM | C3: ID LOTE | D3: ESTADO | E3: PRECIO DE VENTA | F3: SALDO FINANCIADO | G3: FECHA DE VENTA | H3: PLAZO/CUOTAS | I3: FECHAS DE VENCIMIENTO | J3: VALOR CUOTA | K3: FECHA VENCIMIENTO | L3: DÍAS DE VENCIMIENTO | M3: FECHA DE PAGO | N3: VALOR | O3: ESTADO CUOTA | P3: MEDIO DE PAGO | Q3: FECHA VENCIMIENTO | R3: DÍAS DE VENCIMIENTO | S3: FECHA DE PAGO | T3: VALOR | U3: ESTADO CUOTA | V3: MEDIO DE PAGO | W3: FECHA VENCIMIENTO | X3: DÍAS DE VENCIMIENTO | Y3: FECHA DE PAGO | Z3: VALOR | AA3: ESTADO CUOTA | AB3: MEDIO DE PAGO | AC3: FECHA VENCIMIENTO | AD3: DÍAS DE VENCIMIENTO | AE3: FECHA DE PAGO | AF3: VALOR | AG3: ESTADO CUOTA | AH3: MEDIO DE PAGO | AI3: FECHA VENCIMIENTO | AJ3: DÍAS DE VENCIMIENTO | AK3: FECHA DE PAGO | AL3: VALOR | AM3: ESTADO CUOTA | AN3: MEDIO DE PAGO | AO3: FECHA VENCIMIENTO | AP3: DÍAS DE VENCIMIENTO | AQ3: FECHA DE PAGO | AR3: VALOR | AS3: ESTADO CUOTA | AT3: MEDIO DE PAGO | AU3: FECHA VENCIMIENTO | AV3: DÍAS DE VENCIMIENTO | AW3: FECHA DE PAGO | AX3: VALOR | AY3: ESTADO CUOTA | AZ3: MEDIO DE PAGO | BA3: FECHA VENCIMIENTO | BB3: DÍAS DE VENCIMIENTO | BC3: FECHA DE PAGO | BD3: VALOR | BE3: ESTADO CUOTA | BF3: MEDIO DE PAGO | BG3: FECHA VENCIMIENTO | BH3: DÍAS DE VENCIMIENTO | BI3: FECHA DE PAGO | BJ3: VALOR | BK3: ESTADO CUOTA | BL3: MEDIO DE PAGO | BM3: FECHA VENCIMIENTO | BN3: DÍAS DE VENCIMIENTO | BO3: FECHA DE PAGO | BP3: VALOR | BQ3: ESTADO CUOTA | BR3: MEDIO DE PAGO | BS3: FECHA VENCIMIENTO | BT3: DÍAS DE VENCIMIENTO | BU3: FECHA DE PAGO | BV3: VALOR | BW3: ESTADO CUOTA | BX3: MEDIO DE PAGO | BY3: FECHA VENCIMIENTO | BZ3: DÍAS DE VENCIMIENTO | CA3: FECHA DE PAGO | CB3: VALOR | CC3: ESTADO CUOTA | CD3: MEDIO DE PAGO | CE3: FECHA VENCIMIENTO | CF3: DÍAS DE VENCIMIENTO | CG3: FECHA DE PAGO | CH3: VALOR | CI3: ESTADO CUOTA | CJ3: MEDIO DE PAGO | CK3: FECHA VENCIMIENTO | CL3: DÍAS DE VENCIMIENTO | CM3: FECHA DE PAGO | CN3: VALOR | CO3: ESTADO CUOTA | CP3: MEDIO DE PAGO | CQ3: FECHA VENCIMIENTO | CR3: DÍAS DE VENCIMIENTO | CS3: FECHA DE PAGO | CT3: VALOR | CU3: ESTADO CUOTA | CV3: MEDIO DE PAGO | CW3: FECHA VENCIMIENTO | CX3: DÍAS DE VENCIMIENTO | CY3: FECHA DE PAGO | CZ3: VALOR | DA3: ESTADO CUOTA | DB3: MEDIO DE PAGO | DC3: FECHA VENCIMIENTO | DD3: DÍAS DE VENCIMIENTO | DE3: FECHA DE PAGO | DF3: VALOR | DG3: ESTADO CUOTA | DH3: MEDIO DE PAGO | DI3: FECHA VENCIMIENTO | DJ3: DÍAS DE VENCIMIENTO | DK3: FECHA DE PAGO | DL3: VALOR | DM3: ESTADO CUOTA | DN3: MEDIO DE PAGO | DO3: FECHA VENCIMIENTO | DP3: DÍAS DE VENCIMIENTO | DQ3: FECHA DE PAGO | DR3: VALOR | DS3: ESTADO CUOTA | DT3: MEDIO DE PAGO | DU3: FECHA VENCIMIENTO | DV3: DÍAS DE VENCIMIENTO | DW3: FECHA DE PAGO | DX3: VALOR | DY3: ESTADO CUOTA | DZ3: MEDIO DE PAGO | EA3: FECHA VENCIMIENTO | EB3: DÍAS DE VENCIMIENTO | EC3: FECHA DE PAGO | ED3: VALOR | EE3: ESTADO CUOTA | EF3: MEDIO DE PAGO | EG3: FECHA VENCIMIENTO | EH3: DÍAS DE VENCIMIENTO | EI3: FECHA DE PAGO | EJ3: VALOR | EK3: ESTADO CUOTA | EL3: MEDIO DE PAGO | EM3: FECHA VENCIMIENTO | EN3: DÍAS DE VENCIMIENTO | EO3: FECHA DE PAGO | EP3: VALOR | EQ3: ESTADO CUOTA | ER3: MEDIO DE PAGO | ES3: FECHA VENCIMIENTO | ET3: DÍAS DE VENCIMIENTO | EU3: FECHA DE PAGO | EV3: VALOR | EW3: ESTADO CUOTA | EX3: MEDIO DE PAGO | EY3: FECHA VENCIMIENTO | EZ3: DÍAS DE VENCIMIENTO | FA3: FECHA DE PAGO | FB3: VALOR | FC3: ESTADO CUOTA | FD3: MEDIO DE PAGO | FE3: FECHA VENCIMIENTO | FF3: DÍAS DE VENCIMIENTO | FG3: FECHA DE PAGO | FH3: VALOR | FI3: ESTADO CUOTA | FJ3: MEDIO DE PAGO | FK3: FECHA VENCIMIENTO | FL3: DÍAS DE VENCIMIENTO | FM3: FECHA DE PAGO | FN3: VALOR | FO3: ESTADO CUOTA | FP3: MEDIO DE PAGO | FQ3: FECHA VENCIMIENTO | FR3: DÍAS DE VENCIMIENTO | FS3: FECHA DE PAGO | FT3: VALOR | FU3: ESTADO CUOTA | FV3: MEDIO DE PAGO | FW3: FECHA VENCIMIENTO | FX3: DÍAS DE VENCIMIENTO | FY3: FECHA DE PAGO | FZ3: VALOR | GA3: ESTADO CUOTA | GB3: MEDIO DE PAGO | GC3: FECHA VENCIMIENTO | GD3: DÍAS DE VENCIMIENTO | GE3: FECHA DE PAGO | GF3: VALOR | GG3: ESTADO CUOTA | GH3: MEDIO DE PAGO | GI3: FECHA VENCIMIENTO | GJ3: DÍAS DE VENCIMIENTO | GK3: FECHA DE PAGO | GL3: VALOR | GM3: ESTADO CUOTA | GN3: MEDIO DE PAGO | GO3: FECHA VENCIMIENTO | GP3: DÍAS DE VENCIMIENTO | GQ3: FECHA DE PAGO | GR3: VALOR | GS3: ESTADO CUOTA | GT3: MEDIO DE PAGO | GU3: FECHA VENCIMIENTO | GV3: DÍAS DE VENCIMIENTO | GW3: FECHA DE PAGO | GX3: VALOR | GY3: ESTADO CUOTA | GZ3: MEDIO DE PAGO | HA3: FECHA VENCIMIENTO | HB3: DÍAS DE VENCIMIENTO | HC3: FECHA DE PAGO | HD3: VALOR | HE3: ESTADO CUOTA | HF3: MEDIO DE PAGO | HG3: FECHA VENCIMIENTO | HH3: DÍAS DE VENCIMIENTO | HI3: FECHA DE PAGO | HJ3: VALOR | HK3: ESTADO CUOTA | HL3: MEDIO DE PAGO | HM3: FECHA VENCIMIENTO | HN3: DÍAS DE VENCIMIENTO | HO3: FECHA DE PAGO | HP3: VALOR | HQ3: ESTADO CUOTA | HR3: MEDIO DE PAGO | HS3: TOTAL PAGADO | HU3: VALOR CUOTA (LIMPIO) | HW3: RECAUDO MES (VALOR) | HX3: RECAUDO MES (N° CUOTAS)
B4: =VENTAS!A3 | C4: =VENTAS!B3 | D4: =VENTAS!C3 | E4: =VENTAS!D3 | F4: =VENTAS!J3 | G4: =VENTAS!F3 | H4: =VENTAS!K3 | I4: =VENTAS!M3 | J4: =VENTAS!L3 | K4: =IF(N($H4)<1,"",$G4+31) | L4: =IF(K4="","",TODAY()-K4) | O4: =IF(K4="","SIN ESTADO",IF(M4<>"","PAGA",IF(L4>0,"VENCIDA",IF(L4>=-5,"POR VENCER","AL DÍA")))) | Q4: =IF(N($H4)<2,"",IF(K4="","",K4+31)) | R4: =IF(Q4="","",TODAY()-Q4) | U4: =IF(Q4="","SIN ESTADO",IF(S4<>"","PAGA",IF(R4>0,"VENCIDA",IF(R4>=-5,"POR VENCER","AL DÍA")))) | W4: =IF(N($H4)<3,"",IF(Q4="","",Q4+31)) | X4: =IF(W4="","",TODAY()-W4) | AA4: =IF(W4="","SIN ESTADO",IF(Y4<>"","PAGA",IF(X4>0,"VENCIDA",IF(X4>=-5,"POR VENCER","AL DÍA")))) | AC4: =IF(N($H4)<4,"",IF(W4="","",W4+31)) | AD4: =IF(AC4="","",TODAY()-AC4) | AG4: =IF(AC4="","SIN ESTADO",IF(AE4<>"","PAGA",IF(AD4>0,"VENCIDA",IF(AD4>=-5,"POR VENCER","AL DÍA")))) | AI4: =IF(N($H4)<5,"",IF(AC4="","",AC4+31)) | AJ4: =IF(AI4="","",TODAY()-AI4) | AM4: =IF(AI4="","SIN ESTADO",IF(AK4<>"","PAGA",IF(AJ4>0,"VENCIDA",IF(AJ4>=-5,"POR VENCER","AL DÍA")))) | AO4: =IF(N($H4)<6,"",IF(AI4="","",AI4+31)) | AP4: =IF(AO4="","",TODAY()-AO4) | AS4: =IF(AO4="","SIN ESTADO",IF(AQ4<>"","PAGA",IF(AP4>0,"VENCIDA",IF(AP4>=-5,"POR VENCER","AL DÍA")))) | AU4: =IF(N($H4)<7,"",IF(AO4="","",AO4+31)) | AV4: =IF(AU4="","",TODAY()-AU4) | AY4: =IF(AU4="","SIN ESTADO",IF(AW4<>"","PAGA",IF(AV4>0,"VENCIDA",IF(AV4>=-5,"POR VENCER","AL DÍA")))) | BA4: =IF(N($H4)<8,"",IF(AU4="","",AU4+31)) | BB4: =IF(BA4="","",TODAY()-BA4) | BE4: =IF(BA4="","SIN ESTADO",IF(BC4<>"","PAGA",IF(BB4>0,"VENCIDA",IF(BB4>=-5,"POR VENCER","AL DÍA")))) | BG4: =IF(N($H4)<9,"",IF(BA4="","",BA4+31)) | BH4: =IF(BG4="","",TODAY()-BG4) | BK4: =IF(BG4="","SIN ESTADO",IF(BI4<>"","PAGA",IF(BH4>0,"VENCIDA",IF(BH4>=-5,"POR VENCER","AL DÍA")))) | BM4: =IF(N($H4)<10,"",IF(BG4="","",BG4+31)) | BN4: =IF(BM4="","",TODAY()-BM4) | BQ4: =IF(BM4="","SIN ESTADO",IF(BO4<>"","PAGA",IF(BN4>0,"VENCIDA",IF(BN4>=-5,"POR VENCER","AL DÍA")))) | BS4: =IF(N($H4)<11,"",IF(BM4="","",BM4+31)) | BT4: =IF(BS4="","",TODAY()-BS4) | BW4: =IF(BS4="","SIN ESTADO",IF(BU4<>"","PAGA",IF(BT4>0,"VENCIDA",IF(BT4>=-5,"POR VENCER","AL DÍA")))) | BY4: =IF(N($H4)<12,"",IF(BS4="","",BS4+31)) | BZ4: =IF(BY4="","",TODAY()-BY4) | CC4: =IF(BY4="","SIN ESTADO",IF(CA4<>"","PAGA",IF(BZ4>0,"VENCIDA",IF(BZ4>=-5,"POR VENCER","AL DÍA")))) | CE4: =IF(N($H4)<13,"",IF(BY4="","",BY4+31)) | CF4: =IF(CE4="","",TODAY()-CE4) | CI4: =IF(CE4="","SIN ESTADO",IF(CG4<>"","PAGA",IF(CF4>0,"VENCIDA",IF(CF4>=-5,"POR VENCER","AL DÍA")))) | CK4: =IF(N($H4)<14,"",IF(CE4="","",CE4+31)) | CL4: =IF(CK4="","",TODAY()-CK4) | CO4: =IF(CK4="","SIN ESTADO",IF(CM4<>"","PAGA",IF(CL4>0,"VENCIDA",IF(CL4>=-5,"POR VENCER","AL DÍA")))) | CQ4: =IF(N($H4)<15,"",IF(CK4="","",CK4+31)) | CR4: =IF(CQ4="","",TODAY()-CQ4) | CU4: =IF(CQ4="","SIN ESTADO",IF(CS4<>"","PAGA",IF(CR4>0,"VENCIDA",IF(CR4>=-5,"POR VENCER","AL DÍA")))) | CW4: =IF(N($H4)<16,"",IF(CQ4="","",CQ4+31)) | CX4: =IF(CW4="","",TODAY()-CW4) | DA4: =IF(CW4="","SIN ESTADO",IF(CY4<>"","PAGA",IF(CX4>0,"VENCIDA",IF(CX4>=-5,"POR VENCER","AL DÍA")))) | DC4: =IF(N($H4)<17,"",IF(CW4="","",CW4+31)) | DD4: =IF(DC4="","",TODAY()-DC4) | DG4: =IF(DC4="","SIN ESTADO",IF(DE4<>"","PAGA",IF(DD4>0,"VENCIDA",IF(DD4>=-5,"POR VENCER","AL DÍA")))) | DI4: =IF(N($H4)<18,"",IF(DC4="","",DC4+31)) | DJ4: =IF(DI4="","",TODAY()-DI4) | DM4: =IF(DI4="","SIN ESTADO",IF(DK4<>"","PAGA",IF(DJ4>0,"VENCIDA",IF(DJ4>=-5,"POR VENCER","AL DÍA")))) | DO4: =IF(N($H4)<19,"",IF(DI4="","",DI4+31)) | DP4: =IF(DO4="","",TODAY()-DO4) | DS4: =IF(DO4="","SIN ESTADO",IF(DQ4<>"","PAGA",IF(DP4>0,"VENCIDA",IF(DP4>=-5,"POR VENCER","AL DÍA")))) | DU4: =IF(N($H4)<20,"",IF(DO4="","",DO4+31)) | DV4: =IF(DU4="","",TODAY()-DU4) | DY4: =IF(DU4="","SIN ESTADO",IF(DW4<>"","PAGA",IF(DV4>0,"VENCIDA",IF(DV4>=-5,"POR VENCER","AL DÍA")))) | EA4: =IF(N($H4)<21,"",IF(DU4="","",DU4+31)) | EB4: =IF(EA4="","",TODAY()-EA4) | EE4: =IF(EA4="","SIN ESTADO",IF(EC4<>"","PAGA",IF(EB4>0,"VENCIDA",IF(EB4>=-5,"POR VENCER","AL DÍA")))) | EG4: =IF(N($H4)<22,"",IF(EA4="","",EA4+31)) | EH4: =IF(EG4="","",TODAY()-EG4) | EK4: =IF(EG4="","SIN ESTADO",IF(EI4<>"","PAGA",IF(EH4>0,"VENCIDA",IF(EH4>=-5,"POR VENCER","AL DÍA")))) | EM4: =IF(N($H4)<23,"",IF(EG4="","",EG4+31)) | EN4: =IF(EM4="","",TODAY()-EM4) | EQ4: =IF(EM4="","SIN ESTADO",IF(EO4<>"","PAGA",IF(EN4>0,"VENCIDA",IF(EN4>=-5,"POR VENCER","AL DÍA")))) | ES4: =IF(N($H4)<24,"",IF(EM4="","",EM4+31)) | ET4: =IF(ES4="","",TODAY()-ES4) | EW4: =IF(ES4="","SIN ESTADO",IF(EU4<>"","PAGA",IF(ET4>0,"VENCIDA",IF(ET4>=-5,"POR VENCER","AL DÍA")))) | EY4: =IF(N($H4)<25,"",IF(ES4="","",ES4+31)) | EZ4: =IF(EY4="","",TODAY()-EY4) | FC4: =IF(EY4="","SIN ESTADO",IF(FA4<>"","PAGA",IF(EZ4>0,"VENCIDA",IF(EZ4>=-5,"POR VENCER","AL DÍA")))) | FE4: =IF(N($H4)<26,"",IF(EY4="","",EY4+31)) | FF4: =IF(FE4="","",TODAY()-FE4) | FI4: =IF(FE4="","SIN ESTADO",IF(FG4<>"","PAGA",IF(FF4>0,"VENCIDA",IF(FF4>=-5,"POR VENCER","AL DÍA")))) | FK4: =IF(N($H4)<27,"",IF(FE4="","",FE4+31)) | FL4: =IF(FK4="","",TODAY()-FK4) | FO4: =IF(FK4="","SIN ESTADO",IF(FM4<>"","PAGA",IF(FL4>0,"VENCIDA",IF(FL4>=-5,"POR VENCER","AL DÍA")))) | FQ4: =IF(N($H4)<28,"",IF(FK4="","",FK4+31)) | FR4: =IF(FQ4="","",TODAY()-FQ4) | FU4: =IF(FQ4="","SIN ESTADO",IF(FS4<>"","PAGA",IF(FR4>0,"VENCIDA",IF(FR4>=-5,"POR VENCER","AL DÍA")))) | FW4: =IF(N($H4)<29,"",IF(FQ4="","",FQ4+31)) | FX4: =IF(FW4="","",TODAY()-FW4) | GA4: =IF(FW4="","SIN ESTADO",IF(FY4<>"","PAGA",IF(FX4>0,"VENCIDA",IF(FX4>=-5,"POR VENCER","AL DÍA")))) | GC4: =IF(N($H4)<30,"",IF(FW4="","",FW4+31)) | GD4: =IF(GC4="","",TODAY()-GC4) | GG4: =IF(GC4="","SIN ESTADO",IF(GE4<>"","PAGA",IF(GD4>0,"VENCIDA",IF(GD4>=-5,"POR VENCER","AL DÍA")))) | GI4: =IF(N($H4)<31,"",IF(GC4="","",GC4+31)) | GJ4: =IF(GI4="","",TODAY()-GI4) | GM4: =IF(GI4="","SIN ESTADO",IF(GK4<>"","PAGA",IF(GJ4>0,"VENCIDA",IF(GJ4>=-5,"POR VENCER","AL DÍA")))) | GO4: =IF(N($H4)<32,"",IF(GI4="","",GI4+31)) | GP4: =IF(GO4="","",TODAY()-GO4) | GS4: =IF(GO4="","SIN ESTADO",IF(GQ4<>"","PAGA",IF(GP4>0,"VENCIDA",IF(GP4>=-5,"POR VENCER","AL DÍA")))) | GU4: =IF(N($H4)<33,"",IF(GO4="","",GO4+31)) | GV4: =IF(GU4="","",TODAY()-GU4) | GY4: =IF(GU4="","SIN ESTADO",IF(GW4<>"","PAGA",IF(GV4>0,"VENCIDA",IF(GV4>=-5,"POR VENCER","AL DÍA")))) | HA4: =IF(N($H4)<34,"",IF(GU4="","",GU4+31)) | HB4: =IF(HA4="","",TODAY()-HA4) | HE4: =IF(HA4="","SIN ESTADO",IF(HC4<>"","PAGA",IF(HB4>0,"VENCIDA",IF(HB4>=-5,"POR VENCER","AL DÍA")))) | HG4: =IF(N($H4)<35,"",IF(HA4="","",HA4+31)) | HH4: =IF(HG4="","",TODAY()-HG4) | HK4: =IF(HG4="","SIN ESTADO",IF(HI4<>"","PAGA",IF(HH4>0,"VENCIDA",IF(HH4>=-5,"POR VENCER","AL DÍA")))) | HM4: =IF(N($H4)<36,"",IF(HG4="","",HG4+31)) | HN4: =IF(HM4="","",TODAY()-HM4) | HQ4: =IF(HM4="","SIN ESTADO",IF(HO4<>"","PAGA",IF(HN4>0,"VENCIDA",IF(HN4>=-5,"POR VENCER","AL DÍA")))) | HS4: =N4+T4+Z4+AF4+AL4+AR4+AX4+BD4+BJ4+BP4+BV4+CB4+CH4+CN4+CT4+CZ4+DF4+DL4+DR4+DX4+ED4+EJ4+EP4+EV4+FB4+FH4+FN4+FT4+FZ4+GF4+GL4+GR4+GX4+HD4+HJ4+HP4 | HU4: =IFERROR(N($J4),0) | HW4: =SUMPRODUCT((MOD(COLUMN($M4:$HR4)-COLUMN($M4),6)=0)*ISNUMBER($M4:$HR4)*($M4:$HR4>=RESUMEN!$C$26)*($M4:$HR4<=RESUMEN!$C$27)*IFERROR(N($N4:$HS4),0)) | HX4: =SUMPRODUCT((MOD(COLUMN($M4:$HR4)-COLUMN($M4),6)=0)*ISNUMBER($M4:$HR4)*($M4:$HR4>=RESUMEN!$C$26)*($M4:$HR4<=RESUMEN!$C$27))
B5: =VENTAS!A4 | C5: =VENTAS!B4 | D5: =VENTAS!C4 | E5: =VENTAS!D4 | F5: =VENTAS!J4 | G5: =VENTAS!F4 | H5: =VENTAS!K4 | I5: =VENTAS!M4 | J5: =VENTAS!L4 | K5: =IF(N($H5)<1,"",$G5+31) | L5: =IF(K5="","",TODAY()-K5) | M5: 45879 | N5: 1958000 | O5: =IF(K5="","SIN ESTADO",IF(M5<>"","PAGA",IF(L5>0,"VENCIDA",IF(L5>=-5,"POR VENCER","AL DÍA")))) | P5: TRANSFERENCIA | Q5: =IF(N($H5)<2,"",IF(K5="","",K5+31)) | R5: =IF(Q5="","",TODAY()-Q5) | S5: 45911 | T5: 1958000 | U5: =IF(Q5="","SIN ESTADO",IF(S5<>"","PAGA",IF(R5>0,"VENCIDA",IF(R5>=-5,"POR VENCER","AL DÍA")))) | V5: TRANSFERENCIA | W5: =IF(N($H5)<3,"",IF(Q5="","",Q5+31)) | X5: =IF(W5="","",TODAY()-W5) | Y5: 45906 | Z5: 1958000 | AA5: =IF(W5="","SIN ESTADO",IF(Y5<>"","PAGA",IF(X5>0,"VENCIDA",IF(X5>=-5,"POR VENCER","AL DÍA")))) | AB5: TRANSFERENCIA | AC5: =IF(N($H5)<4,"",IF(W5="","",W5+31)) | AD5: =IF(AC5="","",TODAY()-AC5) | AE5: 45955 | AF5: 1958000 | AG5: =IF(AC5="","SIN ESTADO",IF(AE5<>"","PAGA",IF(AD5>0,"VENCIDA",IF(AD5>=-5,"POR VENCER","AL DÍA")))) | AH5: TRANSFERENCIA | AI5: =IF(N($H5)<5,"",IF(AC5="","",AC5+31)) | AJ5: =IF(AI5="","",TODAY()-AI5) | AK5: 45991 | AL5: 1958000 | AM5: =IF(AI5="","SIN ESTADO",IF(AK5<>"","PAGA",IF(AJ5>0,"VENCIDA",IF(AJ5>=-5,"POR VENCER","AL DÍA")))) | AN5: TRANSFERENCIA | AO5: =IF(N($H5)<6,"",IF(AI5="","",AI5+31)) | AP5: =IF(AO5="","",TODAY()-AO5) | AQ5: 46386 | AR5: 1958000 | AS5: =IF(AO5="","SIN ESTADO",IF(AQ5<>"","PAGA",IF(AP5>0,"VENCIDA",IF(AP5>=-5,"POR VENCER","AL DÍA")))) | AT5: TRANSFERENCIA | AU5: =IF(N($H5)<7,"",IF(AO5="","",AO5+31)) | AV5: =IF(AU5="","",TODAY()-AU5) | AW5: 46058 | AX5: 1958000 | AY5: =IF(AU5="","SIN ESTADO",IF(AW5<>"","PAGA",IF(AV5>0,"VENCIDA",IF(AV5>=-5,"POR VENCER","AL DÍA")))) | AZ5: TRANSFERENCIA | BA5: =IF(N($H5)<8,"",IF(AU5="","",AU5+31)) | BB5: =IF(BA5="","",TODAY()-BA5) | BC5: 46094 | BD5: 3000000 | BE5: =IF(BA5="","SIN ESTADO",IF(BC5<>"","PAGA",IF(BB5>0,"VENCIDA",IF(BB5>=-5,"POR VENCER","AL DÍA")))) | BF5: TRANSFERENCIA | BG5: =IF(N($H5)<9,"",IF(BA5="","",BA5+31)) | BH5: =IF(BG5="","",TODAY()-BG5) | BI5: 46096 | BJ5: 3000000 | BK5: =IF(BG5="","SIN ESTADO",IF(BI5<>"","PAGA",IF(BH5>0,"VENCIDA",IF(BH5>=-5,"POR VENCER","AL DÍA")))) | BL5: TRANSFERENCIA | BM5: =IF(N($H5)<10,"",IF(BG5="","",BG5+31)) | BN5: =IF(BM5="","",TODAY()-BM5) | BO5: 46131 | BP5: 5000000 | BQ5: =IF(BM5="","SIN ESTADO",IF(BO5<>"","PAGA",IF(BN5>0,"VENCIDA",IF(BN5>=-5,"POR VENCER","AL DÍA")))) | BR5: TRANSFERENCIA | BS5: =IF(N($H5)<11,"",IF(BM5="","",BM5+31)) | BT5: =IF(BS5="","",TODAY()-BS5) | BU5: 46177 | BV5: 5000000 | BW5: =IF(BS5="","SIN ESTADO",IF(BU5<>"","PAGA",IF(BT5>0,"VENCIDA",IF(BT5>=-5,"POR VENCER","AL DÍA")))) | BX5: TRANSFERENCIA | BY5: =IF(N($H5)<12,"",IF(BS5="","",BS5+31)) | BZ5: =IF(BY5="","",TODAY()-BY5) | CA5: 46223 | CB5: 3000000 | CC5: =IF(BY5="","SIN ESTADO",IF(CA5<>"","PAGA",IF(BZ5>0,"VENCIDA",IF(BZ5>=-5,"POR VENCER","AL DÍA")))) | CD5: TRANSFERENCIA | CE5: =IF(N($H5)<13,"",IF(BY5="","",BY5+31)) | CF5: =IF(CE5="","",TODAY()-CE5) | CG5: 46251 | CH5: 2500000 | CI5: =IF(CE5="","SIN ESTADO",IF(CG5<>"","PAGA",IF(CF5>0,"VENCIDA",IF(CF5>=-5,"POR VENCER","AL DÍA")))) | CJ5: TRANSFERENCIA | CK5: =IF(N($H5)<14,"",IF(CE5="","",CE5+31)) | CL5: =IF(CK5="","",TODAY()-CK5) | CM5: 46259 | CN5: 5000000 | CO5: =IF(CK5="","SIN ESTADO",IF(CM5<>"","PAGA",IF(CL5>0,"VENCIDA",IF(CL5>=-5,"POR VENCER","AL DÍA")))) | CP5: TRANSFERENCIA | CQ5: =IF(N($H5)<15,"",IF(CK5="","",CK5+31)) | CR5: =IF(CQ5="","",TODAY()-CQ5) | CU5: =IF(CQ5="","SIN ESTADO",IF(CS5<>"","PAGA",IF(CR5>0,"VENCIDA",IF(CR5>=-5,"POR VENCER","AL DÍA")))) | CW5: =IF(N($H5)<16,"",IF(CQ5="","",CQ5+31)) | CX5: =IF(CW5="","",TODAY()-CW5) | DA5: =IF(CW5="","SIN ESTADO",IF(CY5<>"","PAGA",IF(CX5>0,"VENCIDA",IF(CX5>=-5,"POR VENCER","AL DÍA")))) | DC5: =IF(N($H5)<17,"",IF(CW5="","",CW5+31)) | DD5: =IF(DC5="","",TODAY()-DC5) | DG5: =IF(DC5="","SIN ESTADO",IF(DE5<>"","PAGA",IF(DD5>0,"VENCIDA",IF(DD5>=-5,"POR VENCER","AL DÍA")))) | DI5: =IF(N($H5)<18,"",IF(DC5="","",DC5+31)) | DJ5: =IF(DI5="","",TODAY()-DI5) | DM5: =IF(DI5="","SIN ESTADO",IF(DK5<>"","PAGA",IF(DJ5>0,"VENCIDA",IF(DJ5>=-5,"POR VENCER","AL DÍA")))) | DO5: =IF(N($H5)<19,"",IF(DI5="","",DI5+31)) | DP5: =IF(DO5="","",TODAY()-DO5) | DS5: =IF(DO5="","SIN ESTADO",IF(DQ5<>"","PAGA",IF(DP5>0,"VENCIDA",IF(DP5>=-5,"POR VENCER","AL DÍA")))) | DU5: =IF(N($H5)<20,"",IF(DO5="","",DO5+31)) | DV5: =IF(DU5="","",TODAY()-DU5) | DY5: =IF(DU5="","SIN ESTADO",IF(DW5<>"","PAGA",IF(DV5>0,"VENCIDA",IF(DV5>=-5,"POR VENCER","AL DÍA")))) | EA5: =IF(N($H5)<21,"",IF(DU5="","",DU5+31)) | EB5: =IF(EA5="","",TODAY()-EA5) | EE5: =IF(EA5="","SIN ESTADO",IF(EC5<>"","PAGA",IF(EB5>0,"VENCIDA",IF(EB5>=-5,"POR VENCER","AL DÍA")))) | EG5: =IF(N($H5)<22,"",IF(EA5="","",EA5+31)) | EH5: =IF(EG5="","",TODAY()-EG5) | EK5: =IF(EG5="","SIN ESTADO",IF(EI5<>"","PAGA",IF(EH5>0,"VENCIDA",IF(EH5>=-5,"POR VENCER","AL DÍA")))) | EM5: =IF(N($H5)<23,"",IF(EG5="","",EG5+31)) | EN5: =IF(EM5="","",TODAY()-EM5) | EQ5: =IF(EM5="","SIN ESTADO",IF(EO5<>"","PAGA",IF(EN5>0,"VENCIDA",IF(EN5>=-5,"POR VENCER","AL DÍA")))) | ES5: =IF(N($H5)<24,"",IF(EM5="","",EM5+31)) | ET5: =IF(ES5="","",TODAY()-ES5) | EW5: =IF(ES5="","SIN ESTADO",IF(EU5<>"","PAGA",IF(ET5>0,"VENCIDA",IF(ET5>=-5,"POR VENCER","AL DÍA")))) | EY5: =IF(N($H5)<25,"",IF(ES5="","",ES5+31)) | EZ5: =IF(EY5="","",TODAY()-EY5) | FC5: =IF(EY5="","SIN ESTADO",IF(FA5<>"","PAGA",IF(EZ5>0,"VENCIDA",IF(EZ5>=-5,"POR VENCER","AL DÍA")))) | FE5: =IF(N($H5)<26,"",IF(EY5="","",EY5+31)) | FF5: =IF(FE5="","",TODAY()-FE5) | FI5: =IF(FE5="","SIN ESTADO",IF(FG5<>"","PAGA",IF(FF5>0,"VENCIDA",IF(FF5>=-5,"POR VENCER","AL DÍA")))) | FK5: =IF(N($H5)<27,"",IF(FE5="","",FE5+31)) | FL5: =IF(FK5="","",TODAY()-FK5) | FO5: =IF(FK5="","SIN ESTADO",IF(FM5<>"","PAGA",IF(FL5>0,"VENCIDA",IF(FL5>=-5,"POR VENCER","AL DÍA")))) | FQ5: =IF(N($H5)<28,"",IF(FK5="","",FK5+31)) | FR5: =IF(FQ5="","",TODAY()-FQ5) | FU5: =IF(FQ5="","SIN ESTADO",IF(FS5<>"","PAGA",IF(FR5>0,"VENCIDA",IF(FR5>=-5,"POR VENCER","AL DÍA")))) | FW5: =IF(N($H5)<29,"",IF(FQ5="","",FQ5+31)) | FX5: =IF(FW5="","",TODAY()-FW5) | GA5: =IF(FW5="","SIN ESTADO",IF(FY5<>"","PAGA",IF(FX5>0,"VENCIDA",IF(FX5>=-5,"POR VENCER","AL DÍA")))) | GC5: =IF(N($H5)<30,"",IF(FW5="","",FW5+31)) | GD5: =IF(GC5="","",TODAY()-GC5) | GG5: =IF(GC5="","SIN ESTADO",IF(GE5<>"","PAGA",IF(GD5>0,"VENCIDA",IF(GD5>=-5,"POR VENCER","AL DÍA")))) | GI5: =IF(N($H5)<31,"",IF(GC5="","",GC5+31)) | GJ5: =IF(GI5="","",TODAY()-GI5) | GM5: =IF(GI5="","SIN ESTADO",IF(GK5<>"","PAGA",IF(GJ5>0,"VENCIDA",IF(GJ5>=-5,"POR VENCER","AL DÍA")))) | GO5: =IF(N($H5)<32,"",IF(GI5="","",GI5+31)) | GP5: =IF(GO5="","",TODAY()-GO5) | GS5: =IF(GO5="","SIN ESTADO",IF(GQ5<>"","PAGA",IF(GP5>0,"VENCIDA",IF(GP5>=-5,"POR VENCER","AL DÍA")))) | GU5: =IF(N($H5)<33,"",IF(GO5="","",GO5+31)) | GV5: =IF(GU5="","",TODAY()-GU5) | GY5: =IF(GU5="","SIN ESTADO",IF(GW5<>"","PAGA",IF(GV5>0,"VENCIDA",IF(GV5>=-5,"POR VENCER","AL DÍA")))) | HA5: =IF(N($H5)<34,"",IF(GU5="","",GU5+31)) | HB5: =IF(HA5="","",TODAY()-HA5) | HE5: =IF(HA5="","SIN ESTADO",IF(HC5<>"","PAGA",IF(HB5>0,"VENCIDA",IF(HB5>=-5,"POR VENCER","AL DÍA")))) | HG5: =IF(N($H5)<35,"",IF(HA5="","",HA5+31)) | HH5: =IF(HG5="","",TODAY()-HG5) | HK5: =IF(HG5="","SIN ESTADO",IF(HI5<>"","PAGA",IF(HH5>0,"VENCIDA",IF(HH5>=-5,"POR VENCER","AL DÍA")))) | HM5: =IF(N($H5)<36,"",IF(HG5="","",HG5+31)) | HN5: =IF(HM5="","",TODAY()-HM5) | HQ5: =IF(HM5="","SIN ESTADO",IF(HO5<>"","PAGA",IF(HN5>0,"VENCIDA",IF(HN5>=-5,"POR VENCER","AL DÍA")))) | HS5: =N5+T5+Z5+AF5+AL5+AR5+AX5+BD5+BJ5+BP5+BV5+CB5+CH5+CN5+CT5+CZ5+DF5+DL5+DR5+DX5+ED5+EJ5+EP5+EV5+FB5+FH5+FN5+FT5+FZ5+GF5+GL5+GR5+GX5+HD5+HJ5+HP5 | HU5: =IFERROR(N($J5),0) | HW5: =SUMPRODUCT((MOD(COLUMN($M5:$HR5)-COLUMN($M5),6)=0)*ISNUMBER($M5:$HR5)*($M5:$HR5>=RESUMEN!$C$26)*($M5:$HR5<=RESUMEN!$C$27)*IFERROR(N($N5:$HS5),0)) | HX5: =SUMPRODUCT((MOD(COLUMN($M5:$HR5)-COLUMN($M5),6)=0)*ISNUMBER($M5:$HR5)*($M5:$HR5>=RESUMEN!$C$26)*($M5:$HR5<=RESUMEN!$C$27))
B6: =VENTAS!A5 | C6: =VENTAS!B5 | D6: =VENTAS!C5 | E6: =VENTAS!D5 | F6: =VENTAS!J5 | G6: =VENTAS!F5 | H6: =VENTAS!K5 | I6: =VENTAS!M5 | J6: =VENTAS!L5 | K6: =IF(N($H6)<1,"",$G6+31) | L6: =IF(K6="","",TODAY()-K6) | M6: 45920 | N6: 850000 | O6: =IF(K6="","SIN ESTADO",IF(M6<>"","PAGA",IF(L6>0,"VENCIDA",IF(L6>=-5,"POR VENCER","AL DÍA")))) | P6: TRANSFERENCIA | Q6: =IF(N($H6)<2,"",IF(K6="","",K6+31)) | R6: =IF(Q6="","",TODAY()-Q6) | S6: 45951 | T6: 850000 | U6: =IF(Q6="","SIN ESTADO",IF(S6<>"","PAGA",IF(R6>0,"VENCIDA",IF(R6>=-5,"POR VENCER","AL DÍA")))) | V6: TRANSFERENCIA | W6: =IF(N($H6)<3,"",IF(Q6="","",Q6+31)) | X6: =IF(W6="","",TODAY()-W6) | Y6: 45982 | Z6: 850000 | AA6: =IF(W6="","SIN ESTADO",IF(Y6<>"","PAGA",IF(X6>0,"VENCIDA",IF(X6>=-5,"POR VENCER","AL DÍA")))) | AB6: TRANSFERENCIA | AC6: =IF(N($H6)<4,"",IF(W6="","",W6+31)) | AD6: =IF(AC6="","",TODAY()-AC6) | AE6: 45997 | AF6: 8000000 | AG6: =IF(AC6="","SIN ESTADO",IF(AE6<>"","PAGA",IF(AD6>0,"VENCIDA",IF(AD6>=-5,"POR VENCER","AL DÍA")))) | AH6: EFECTIVO | AI6: =IF(N($H6)<5,"",IF(AC6="","",AC6+31)) | AJ6: =IF(AI6="","",TODAY()-AI6) | AK6: 46013 | AL6: 850000 | AM6: =IF(AI6="","SIN ESTADO",IF(AK6<>"","PAGA",IF(AJ6>0,"VENCIDA",IF(AJ6>=-5,"POR VENCER","AL DÍA")))) | AN6: TRANSFERENCIA | AO6: =IF(N($H6)<6,"",IF(AI6="","",AI6+31)) | AP6: =IF(AO6="","",TODAY()-AO6) | AQ6: 46014 | AR6: 5600000 | AS6: =IF(AO6="","SIN ESTADO",IF(AQ6<>"","PAGA",IF(AP6>0,"VENCIDA",IF(AP6>=-5,"POR VENCER","AL DÍA")))) | AT6: EFECTIVO | AU6: =IF(N($H6)<7,"",IF(AO6="","",AO6+31)) | AV6: =IF(AU6="","",TODAY()-AU6) | AY6: =IF(AU6="","SIN ESTADO",IF(AW6<>"","PAGA",IF(AV6>0,"VENCIDA",IF(AV6>=-5,"POR VENCER","AL DÍA")))) | BA6: =IF(N($H6)<8,"",IF(AU6="","",AU6+31)) | BB6: =IF(BA6="","",TODAY()-BA6) | BE6: =IF(BA6="","SIN ESTADO",IF(BC6<>"","PAGA",IF(BB6>0,"VENCIDA",IF(BB6>=-5,"POR VENCER","AL DÍA")))) | BG6: =IF(N($H6)<9,"",IF(BA6="","",BA6+31)) | BH6: =IF(BG6="","",TODAY()-BG6) | BK6: =IF(BG6="","SIN ESTADO",IF(BI6<>"","PAGA",IF(BH6>0,"VENCIDA",IF(BH6>=-5,"POR VENCER","AL DÍA")))) | BM6: =IF(N($H6)<10,"",IF(BG6="","",BG6+31)) | BN6: =IF(BM6="","",TODAY()-BM6) | BQ6: =IF(BM6="","SIN ESTADO",IF(BO6<>"","PAGA",IF(BN6>0,"VENCIDA",IF(BN6>=-5,"POR VENCER","AL DÍA")))) | BS6: =IF(N($H6)<11,"",IF(BM6="","",BM6+31)) | BT6: =IF(BS6="","",TODAY()-BS6) | BW6: =IF(BS6="","SIN ESTADO",IF(BU6<>"","PAGA",IF(BT6>0,"VENCIDA",IF(BT6>=-5,"POR VENCER","AL DÍA")))) | BY6: =IF(N($H6)<12,"",IF(BS6="","",BS6+31)) | BZ6: =IF(BY6="","",TODAY()-BY6) | CC6: =IF(BY6="","SIN ESTADO",IF(CA6<>"","PAGA",IF(BZ6>0,"VENCIDA",IF(BZ6>=-5,"POR VENCER","AL DÍA")))) | CE6: =IF(N($H6)<13,"",IF(BY6="","",BY6+31)) | CF6: =IF(CE6="","",TODAY()-CE6) | CI6: =IF(CE6="","SIN ESTADO",IF(CG6<>"","PAGA",IF(CF6>0,"VENCIDA",IF(CF6>=-5,"POR VENCER","AL DÍA")))) | CK6: =IF(N($H6)<14,"",IF(CE6="","",CE6+31)) | CL6: =IF(CK6="","",TODAY()-CK6) | CO6: =IF(CK6="","SIN ESTADO",IF(CM6<>"","PAGA",IF(CL6>0,"VENCIDA",IF(CL6>=-5,"POR VENCER","AL DÍA")))) | CQ6: =IF(N($H6)<15,"",IF(CK6="","",CK6+31)) | CR6: =IF(CQ6="","",TODAY()-CQ6) | CU6: =IF(CQ6="","SIN ESTADO",IF(CS6<>"","PAGA",IF(CR6>0,"VENCIDA",IF(CR6>=-5,"POR VENCER","AL DÍA")))) | CW6: =IF(N($H6)<16,"",IF(CQ6="","",CQ6+31)) | CX6: =IF(CW6="","",TODAY()-CW6) | DA6: =IF(CW6="","SIN ESTADO",IF(CY6<>"","PAGA",IF(CX6>0,"VENCIDA",IF(CX6>=-5,"POR VENCER","AL DÍA")))) | DC6: =IF(N($H6)<17,"",IF(CW6="","",CW6+31)) | DD6: =IF(DC6="","",TODAY()-DC6) | DG6: =IF(DC6="","SIN ESTADO",IF(DE6<>"","PAGA",IF(DD6>0,"VENCIDA",IF(DD6>=-5,"POR VENCER","AL DÍA")))) | DI6: =IF(N($H6)<18,"",IF(DC6="","",DC6+31)) | DJ6: =IF(DI6="","",TODAY()-DI6) | DM6: =IF(DI6="","SIN ESTADO",IF(DK6<>"","PAGA",IF(DJ6>0,"VENCIDA",IF(DJ6>=-5,"POR VENCER","AL DÍA")))) | DO6: =IF(N($H6)<19,"",IF(DI6="","",DI6+31)) | DP6: =IF(DO6="","",TODAY()-DO6) | DS6: =IF(DO6="","SIN ESTADO",IF(DQ6<>"","PAGA",IF(DP6>0,"VENCIDA",IF(DP6>=-5,"POR VENCER","AL DÍA")))) | DU6: =IF(N($H6)<20,"",IF(DO6="","",DO6+31)) | DV6: =IF(DU6="","",TODAY()-DU6) | DY6: =IF(DU6="","SIN ESTADO",IF(DW6<>"","PAGA",IF(DV6>0,"VENCIDA",IF(DV6>=-5,"POR VENCER","AL DÍA")))) | EA6: =IF(N($H6)<21,"",IF(DU6="","",DU6+31)) | EB6: =IF(EA6="","",TODAY()-EA6) | EE6: =IF(EA6="","SIN ESTADO",IF(EC6<>"","PAGA",IF(EB6>0,"VENCIDA",IF(EB6>=-5,"POR VENCER","AL DÍA")))) | EG6: =IF(N($H6)<22,"",IF(EA6="","",EA6+31)) | EH6: =IF(EG6="","",TODAY()-EG6) | EK6: =IF(EG6="","SIN ESTADO",IF(EI6<>"","PAGA",IF(EH6>0,"VENCIDA",IF(EH6>=-5,"POR VENCER","AL DÍA")))) | EM6: =IF(N($H6)<23,"",IF(EG6="","",EG6+31)) | EN6: =IF(EM6="","",TODAY()-EM6) | EQ6: =IF(EM6="","SIN ESTADO",IF(EO6<>"","PAGA",IF(EN6>0,"VENCIDA",IF(EN6>=-5,"POR VENCER","AL DÍA")))) | ES6: =IF(N($H6)<24,"",IF(EM6="","",EM6+31)) | ET6: =IF(ES6="","",TODAY()-ES6) | EW6: =IF(ES6="","SIN ESTADO",IF(EU6<>"","PAGA",IF(ET6>0,"VENCIDA",IF(ET6>=-5,"POR VENCER","AL DÍA")))) | EY6: =IF(N($H6)<25,"",IF(ES6="","",ES6+31)) | EZ6: =IF(EY6="","",TODAY()-EY6) | FC6: =IF(EY6="","SIN ESTADO",IF(FA6<>"","PAGA",IF(EZ6>0,"VENCIDA",IF(EZ6>=-5,"POR VENCER","AL DÍA")))) | FE6: =IF(N($H6)<26,"",IF(EY6="","",EY6+31)) | FF6: =IF(FE6="","",TODAY()-FE6) | FI6: =IF(FE6="","SIN ESTADO",IF(FG6<>"","PAGA",IF(FF6>0,"VENCIDA",IF(FF6>=-5,"POR VENCER","AL DÍA")))) | FK6: =IF(N($H6)<27,"",IF(FE6="","",FE6+31)) | FL6: =IF(FK6="","",TODAY()-FK6) | FO6: =IF(FK6="","SIN ESTADO",IF(FM6<>"","PAGA",IF(FL6>0,"VENCIDA",IF(FL6>=-5,"POR VENCER","AL DÍA")))) | FQ6: =IF(N($H6)<28,"",IF(FK6="","",FK6+31)) | FR6: =IF(FQ6="","",TODAY()-FQ6) | FU6: =IF(FQ6="","SIN ESTADO",IF(FS6<>"","PAGA",IF(FR6>0,"VENCIDA",IF(FR6>=-5,"POR VENCER","AL DÍA")))) | FW6: =IF(N($H6)<29,"",IF(FQ6="","",FQ6+31)) | FX6: =IF(FW6="","",TODAY()-FW6) | GA6: =IF(FW6="","SIN ESTADO",IF(FY6<>"","PAGA",IF(FX6>0,"VENCIDA",IF(FX6>=-5,"POR VENCER","AL DÍA")))) | GC6: =IF(N($H6)<30,"",IF(FW6="","",FW6+31)) | GD6: =IF(GC6="","",TODAY()-GC6) | GG6: =IF(GC6="","SIN ESTADO",IF(GE6<>"","PAGA",IF(GD6>0,"VENCIDA",IF(GD6>=-5,"POR VENCER","AL DÍA")))) | GI6: =IF(N($H6)<31,"",IF(GC6="","",GC6+31)) | GJ6: =IF(GI6="","",TODAY()-GI6) | GM6: =IF(GI6="","SIN ESTADO",IF(GK6<>"","PAGA",IF(GJ6>0,"VENCIDA",IF(GJ6>=-5,"POR VENCER","AL DÍA")))) | GO6: =IF(N($H6)<32,"",IF(GI6="","",GI6+31)) | GP6: =IF(GO6="","",TODAY()-GO6) | GS6: =IF(GO6="","SIN ESTADO",IF(GQ6<>"","PAGA",IF(GP6>0,"VENCIDA",IF(GP6>=-5,"POR VENCER","AL DÍA")))) | GU6: =IF(N($H6)<33,"",IF(GO6="","",GO6+31)) | GV6: =IF(GU6="","",TODAY()-GU6) | GY6: =IF(GU6="","SIN ESTADO",IF(GW6<>"","PAGA",IF(GV6>0,"VENCIDA",IF(GV6>=-5,"POR VENCER","AL DÍA")))) | HA6: =IF(N($H6)<34,"",IF(GU6="","",GU6+31)) | HB6: =IF(HA6="","",TODAY()-HA6) | HE6: =IF(HA6="","SIN ESTADO",IF(HC6<>"","PAGA",IF(HB6>0,"VENCIDA",IF(HB6>=-5,"POR VENCER","AL DÍA")))) | HG6: =IF(N($H6)<35,"",IF(HA6="","",HA6+31)) | HH6: =IF(HG6="","",TODAY()-HG6) | HK6: =IF(HG6="","SIN ESTADO",IF(HI6<>"","PAGA",IF(HH6>0,"VENCIDA",IF(HH6>=-5,"POR VENCER","AL DÍA")))) | HM6: =IF(N($H6)<36,"",IF(HG6="","",HG6+31)) | HN6: =IF(HM6="","",TODAY()-HM6) | HQ6: =IF(HM6="","SIN ESTADO",IF(HO6<>"","PAGA",IF(HN6>0,"VENCIDA",IF(HN6>=-5,"POR VENCER","AL DÍA")))) | HS6: =N6+T6+Z6+AF6+AL6+AR6+AX6+BD6+BJ6+BP6+BV6+CB6+CH6+CN6+CT6+CZ6+DF6+DL6+DR6+DX6+ED6+EJ6+EP6+EV6+FB6+FH6+FN6+FT6+FZ6+GF6+GL6+GR6+GX6+HD6+HJ6+HP6 | HU6: =IFERROR(N($J6),0) | HW6: =SUMPRODUCT((MOD(COLUMN($M6:$HR6)-COLUMN($M6),6)=0)*ISNUMBER($M6:$HR6)*($M6:$HR6>=RESUMEN!$C$26)*($M6:$HR6<=RESUMEN!$C$27)*IFERROR(N($N6:$HS6),0)) | HX6: =SUMPRODUCT((MOD(COLUMN($M6:$HR6)-COLUMN($M6),6)=0)*ISNUMBER($M6:$HR6)*($M6:$HR6>=RESUMEN!$C$26)*($M6:$HR6<=RESUMEN!$C$27))
